Workbook

Sheet Consignes
A1: Consignes pour analyser les données d'un tri de carte ouvert
A2: Consigne générale : modifier uniquement les cellules en jaune
A3: Feuille Cartes
A4: encoder les libellés de cartes dans la zone jaune et laisser les cellules inutiles vides
A5: encoder les libellés par ordre alphabétique pour que la numérotation ne définisse pas les catégories
A6: indiquer les numéros au verso des cartes au crayon pour faciliter l'encodage
A7: astuce : faire du publipostage pour créer un document Word avec les cartes en utilisant les documents au format d'étiquette
A8: Jouer le tri de cartes avec au moins 5 participants
A9: Feuille Réponses
A10: encoder les réponses des participants dans la zone jaune et laissez les cellules inutiles vides
A11: Feuille Similarités
A12: la matrice de similarité indique les cartes qui sont le plus souvent associées dans les tris indépendamment des libellés de catégories
... A17: Source : lien

Sheet Cartes
B1: Libellé de carte
A2: 1 | B2: Libellé 1
A3: 2 | B3: Libellé 2
A4: 3 | B4: Libellé 3
A5: 4 | B5: Libellé 4
A6: 5 | B6: Libellé 5
A7: 6 | B7: Libellé 6
A8: 7 | B8: Libellé 7
A9: 8 | B9: Libellé 8
A10: 9 | B10: Libellé 9
A11: 10 | B11: Libellé 10
A12: 11 | B12: Libellé 11
A13: 12 | B13: Libellé 12
... A101: 100 | B101: Libellé 100

Sheet Réponses
B1: Participant 1 | C1: Participant 2 | D1: Participant 3 | E1: Participant 4 | F1: Participant 5 | G1: Participant 6 | H1: Participant 7 | I1: Participant 8 | J1: Participant 9 | K1: Participant 10 | L1: Participant 11 | M1: Participant 12 | N1: Participant 13 | O1: Participant 14 | P1: Participant 15 | Q1: Participant 16 | R1: Participant 17 | S1: Participant 18 | T1: Participant 19 | U1: Participant 20
A2: 1 | B2: 14 | C2: 14 | D2: 11 | E2: 14 | F2: 2 | G2: 14 | H2: 3 | I2: 14 | J2: 2 | K2: 3 | L2: 14 | M2: 3 | N2: 11 | O2: 3 | P2: 14 | Q2: 14 | R2: 3 | S2: 14 | T2: 11 | U2: 14
A3: 2 | B3: 3 | C3: 8 | D3: 8 | E3: 8 | F3: 8 | G3: 9 | H3: 2 | I3: 9 | J3: 9 | K3: 9 | L3: 9 | M3: 9 | N3: 9 | O3: 9 | P3: 9 | Q3: 9 | R3: 9 | S3: 9 | T3: 9 | U3: 3
A4: 3 | B4: 19 | C4: 19 | D4: 19 | E4: 3 | F4: 19 | G4: 19 | H4: 19 | I4: 19 | J4: 19 | K4: 19 | L4: 19 | M4: 19 | N4: 19 | O4: 19 | P4: 19 | Q4: 19 | R4: 19 | S4: 19 | T4: 19 | U4: 19
A5: 4 | B5: 18 | C5: 18 | D5: 18 | E5: 18 | F5: 18 | G5: 18 | H5: 18 | I5: 18 | J5: 18 | K5: 18 | L5: 18 | M5: 18 | N5: 18 | O5: 18 | P5: 18 | Q5: 18 | R5: 18 | S5: 18 | T5: 18 | U5: 18
A6: 5 | B6: 9 | C6: 9 | D6: 9 | E6: 9 | F6: 9 | G6: 9 | H6: 9 | I6: 9 | J6: 9 | K6: 9 | L6: 9 | M6: 9 | N6: 9 | O6: 9 | P6: 9 | Q6: 9 | R6: 9 | S6: 9 | T6: 9 | U6: 9
A7: 6 | B7: 1 | C7: 1 | D7: 1 | E7: 1 | F7: 1 | G7: 1 | H7: 1 | I7: 1 | J7: 1 | K7: 1 | L7: 1 | M7: 1 | N7: 1 | O7: 1 | P7: 1 | Q7: 1 | R7: 1 | S7: 1 | T7: 1 | U7: 1
A8: 7 | B8: 15 | C8: 15 | D8: 15 | E8: 15 | F8: 15 | G8: 15 | H8: 15 | I8: 15 | J8: 15 | K8: 15 | L8: 15 | M8: 15 | N8: 15 | O8: 15 | P8: 15 | Q8: 15 | R8: 15 | S8: 15 | T8: 15 | U8: 15
A9: 8 | B9: 2 | C9: 2 | D9: 2 | E9: 2 | F9: 2 | G9: 2 | H9: 2 | I9: 2 | J9: 2 | K9: 2 | L9: 2 | M9: 2 | N9: 2 | O9: 2 | P9: 2 | Q9: 2 | R9: 2 | S9: 2 | T9: 2 | U9: 2
A10: 9 | B10: 7 | C10: 7 | D10: 7 | E10: 7 | F10: 7 | G10: 7 | H10: 7 | I10: 7 | J10: 7 | K10: 7 | L10: 7 | M10: 7 | N10: 7 | O10: 7 | P10: 7 | Q10: 7 | R10: 7 | S10: 7 | T10: 7 | U10: 7
A11: 10 | B11: 18 | C11: 18 | D11: 18 | E11: 18 | F11: 18 | G11: 18 | H11: 18 | I11: 18 | J11: 18 | K11: 18 | L11: 18 | M11: 18 | N11: 18 | O11: 18 | P11: 18 | Q11: 18 | R11: 18 | S11: 18 | T11: 18 | U11: 18
A12: 11 | B12: 2 | C12: 2 | D12: 2 | E12: 2 | F12: 2 | G12: 2 | H12: 2 | I12: 2 | J12: 2 | K12: 2 | L12: 2 | M12: 2 | N12: 2 | O12: 2 | P12: 2 | Q12: 2 | R12: 2 | S12: 2 | T12: 2 | U12: 2
A13: 12 | B13: 1 | C13: 1 | D13: 1 | E13: 1 | F13: 1 | G13: 1 | H13: 1 | I13: 1 | J13: 1 | K13: 1 | L13: 1 | M13: 1 | N13: 1 | O13: 1 | P13: 1 | Q13: 1 | R13: 1 | S13: 1 | T13: 1 | U13: 1
... A39: 38 | B39: 14 | C39: 14 | D39: 14 | E39: 14 | F39: 3 | G39: 14 | H39: 3 | I39: 14 | J39: 14 | K39: 3 | L39: 14 | M39: 3 | N39: 14 | O39: 14 | P39: 14 | Q39: 14 | R39: 3 | S39: 14 | T39: 14 | U39: 14
A40: 39 | B40: 4 | C40: 4 | D40: 4 | E40: 4 | G40: 4 | H40: 4 | I40: 4 | J40: 4 | K40: 4 | L40: 4 | M40: 4 | N40: 4 | O40: 4 | P40: 4 | Q40: 4 | R40: 4 | S40: 4 | T40: 4 | U40: 4
A41: 40 | B41: 3 | C41: 3 | D41: 3 | E41: 3 | F41: 3 | G41: 3 | H41: 3 | I41: 3 | J41: 3 | K41: 3 | L41: 3 | M41: 3 | N41: 3 | O41: 3 | P41: 3 | Q41: 3 | R41: 3 | S41: 3 | T41: 3 | U41: 3
A42: 41 | B42: 10 | C42: 10 | D42: 10 | E42: 10 | F42: 10 | G42: 10 | H42: 10 | I42: 10 | J42: 10 | K42: 10 | L42: 10 | M42: 10 | N42: 10 | O42: 10 | P42: 10 | Q42: 10 | R42: 10 | S42: 10 | T42: 10 | U42: 10
A43: 42 | B43: 9 | C43: 9 | D43: 9 | E43: 9 | F43: 9 | G43: 9 | H43: 9 | I43: 9 | J43: 9 | K43: 9 | L43: 9 | M43: 9 | N43: 9 | O43: 9 | P43: 9 | Q43: 9 | R43: 9 | S43: 9 | T43: 9 | U43: 9
A44: 43 | B44: 10 | C44: 10 | D44: 10 | E44: 10 | F44: 10 | G44: 10 | H44: 10 | I44: 10 | J44: 10 | K44: 10 | L44: 10 | M44: 10 | N44: 10 | O44: 10 | P44: 10 | Q44: 10 | R44: 10 | S44: 10 | T44: 10 | U44: 10
A45: 44 | B45: 2 | C45: 2 | D45: 2 | E45: 2 | F45: 2 | G45: 2 | H45: 2 | I45: 2 | J45: 2 | K45: 2 | L45: 2 | M45: 2 | N45: 2 | O45: 2 | P45: 2 | Q45: 2 | R45: 2 | S45: 2 | T45: 2 | U45: 2
A46: 45 | B46: 8 | C46: 8 | D46: 8 | E46: 8 | F46: 8 | G46: 8 | H46: 8 | I46: 8 | J46: 8 | K46: 8 | L46: 8 | M46: 8 | N46: 8 | O46: 8 | P46: 8 | Q46: 8 | R46: 8 | S46: 8 | T46: 8 | U46: 8
A47: 46 | B47: 4 | C47: 4 | D47: 4 | E47: 4 | F47: 4 | G47: 4 | H47: 4 | I47: 4 | J47: 4 | K47: 4 | L47: 4 | M47: 4 | N47: 4 | O47: 4 | P47: 4 | Q47: 4 | R47: 4 | S47: 4 | T47: 4 | U47: 4
A48: 47 | B48: 17 | C48: 17 | D48: 17 | E48: 17 | F48: 17 | G48: 17 | H48: 17 | I48: 17 | J48: 17 | K48: 17 | L48: 17 | M48: 17 | N48: 17 | O48: 17 | P48: 17 | Q48: 17 | R48: 17 | S48: 17 | T48: 17 | U48: 17
A49: 48 | B49: 11 | C49: 11 | D49: 11 | E49: 11 | F49: 11 | G49: 11 | H49: 11 | I49: 11 | J49: 11 | K49: 11 | L49: 11 | M49: 11 | N49: 11 | O49: 11 | P49: 11 | Q49: 11 | R49: 11 | S49: 11 | T49: 11 | U49: 11
A50: 49 | B50: 5 | C50: 5 | D50: 5 | E50: 5 | F50: 5 | G50: 5 | H50: 5 | I50: 5 | J50: 5 | K50: 5 | L50: 5 | M50: 5 | N50: 5 | O50: 5 | P50: 5 | Q50: 5 | R50: 5 | S50: 5 | T50: 5 | U50: 5
A51: 50 | B51: 9 | C51: 9 | D51: 9 | E51: 9 | F51: 9 | G51: 9 | H51: 9 | I51: 9 | J51: 9 | K51: 9 | L51: 9 | M51: 9 | N51: 9 | O51: 9 | P51: 9 | Q51: 9 | R51: 9 | S51: 9 | T51: 9 | U51: 9
A52: 51 | B52: 3 | C52: 3 | D52: 3 | E52: 3 | F52: 3 | G52: 3 | H52: 3 | I52: 3 | J52: 3 | K52: 3 | L52: 3 | M52: 3 | N52: 3 | O52: 3 | P52: 3 | Q52: 3 | R52: 3 | S52: 3 | T52: 3 | U52: 3
... A101: 100 | B101: 17 | C101: 17 | D101: 17 | E101: 17 | F101: 17 | G101: 17 | H101: 17 | I101: 17 | J101: 17 | K101: 17 | L101: 17 | M101: 17 | N101: 17 | O101: 17 | P101: 17 | Q101: 17 | R101: 17 | S101: 17 | T101: 17 | U101: 17

Sheet Similarités
B1: 1 | C1: 2 | D1: 3 | E1: 4 | F1: 5 | G1: 6 | H1: 7 | I1: 8 | J1: 9 | K1: 10 | L1: 11 | M1: 12 | N1: 13 | O1: 14 | P1: 15 | Q1: 16 | R1: 17 | S1: 18 | T1: 19 | U1: 20 | V1: 21 | W1: 22 | X1: 23 | Y1: 24 | Z1: 25 | AA1: 26 | AB1: 27 | AC1: 28 | AD1: 29 | AE1: 30 | AF1: 31 | AG1: 32 | AH1: 33 | AI1: 34 | AJ1: 35 | AK1: 36 | AL1: 37 | AM1: 38 | AN1: 39 | AO1: 40 | AP1: 41 | AQ1: 42 | AR1: 43 | AS1: 44 | AT1: 45 | AU1: 46 | AV1: 47 | AW1: 48 | AX1: 49 | AY1: 50 | AZ1: 51 | BA1: 52 | BB1: 53 | BC1: 54 | BD1: 55 | BE1: 56 | BF1: 57 | BG1: 58 | BH1: 59 | BI1: 60 | BJ1: 61 | BK1: 62 | BL1: 63 | BM1: 64 | BN1: 65 | BO1: 66 | BP1: 67 | BQ1: 68 | BR1: 69 | BS1: 70 | BT1: 71 | BU1: 72 | BV1: 73 | BW1: 74 | BX1: 75 | BY1: 76 | BZ1: 77 | CA1: 78 | CB1: 79 | CC1: 80 | CD1: 81 | CE1: 82 | CF1: 83 | CG1: 84 | CH1: 85 | CI1: 86 | CJ1: 87 | CK1: 88 | CL1: 89 | CM1: 90 | CN1: 91 | CO1: 92 | CP1: 93 | CQ1: 94 | CR1: 95 | CS1: 96 | CT1: 97 | CU1: 98 | CV1: 99 | CW1: 100
A2: 1 | B2: {=IFERROR( SUMPRODUCT( (INDEX(Réponses!$B$2:$U$101,MATCH($A2,Réponses!$A$2:$A$101,0),)=INDEX(Réponses!$B$2:$U$101,MATCH(B$1,Réponses!$A$2:$A$101,0),))* (INDEX(Réponses!$B$2:$U$101,MATCH($A2,Réponses!$A$2:$A$101,0),)<>"")* (INDEX(Réponses!$B$2:$U$101,MATCH(B$1,Réponses!$A$2:$A$101,0),)<>"") ) /MAX(1,SUMPRODUCT( (INDEX(Réponses!$B$2:$U$101,MATCH($A2,Réponses!$A$2:$A$101,0),)<>"")* (INDEX(Réponses!$B$2:$U$101,MATCH(B$1,Réponses!$A$2:$A$101,0),)<>"") )),"")} -> 1 | C2: {=IFERROR( SUMPRODUCT( (INDEX(Réponses!$B$2:$U$101,MATCH($A2,Réponses!$A$2:$A$101,0),)=INDEX(Réponses!$B$2:$U$101,MATCH(C$1,Réponses!$A$2:$A$101,0),))* (INDEX(Réponses!$B$2:$U$101,MATCH($A2,Réponses!$A$2:$A$101,0),)<>"")* (INDEX(Réponses!$B$2:$U$101,MATCH(C$1,Réponses!$A$2:$A$101,0),)<>"") ) /MAX(1,SUMPRODUCT( (INDEX(Réponses!$B$2:$U$101,MATCH($A2,Réponses!$A$2:$A$101,0),)<>"")* (INDEX(Réponses!$B$2:$U$101,MATCH(C$1,Réponses!$A$2:$A$101,0),)<>"") )),"")} -> 0 | D2: {=IFERROR( SUMPRODUCT( (INDEX(Réponses!$B$2:$U$101,MATCH($A2,Réponses!$A$2:$A$101,0),)=INDEX(Réponses!$B$2:$U$101,MATCH(D$1,Réponses!$A$2:$A$101,0),))* (INDEX(Réponses!$B$2:$U$101,MATCH($A2,Réponses!$A$2:$A$101,0),)<>"")* (INDEX(Réponses!$B$2:$U$101,MATCH(D$1,Réponses!$A$2:$A$101,0),)<>"") ) /MAX(1,SUMPRODUCT( (INDEX(Réponses!$B$2:$U$101,MATCH($A2,Réponses!$A$2:$A$101,0),)<>"")* (INDEX(Réponses!$B$2:$U$101,MATCH(D$1,Réponses!$A$2:$A$101,0),)<>"") )),"")} -> 0 | E2: {=IFERROR( SUMPRODUCT( (INDEX(Réponses!$B$2:$U$101,MATCH($A2,Réponses!$A$2:$A$101,0),)=INDEX(Réponses!$B$2:$U$101,MATCH(E$1,Réponses!$A$2:$A$101,0),))* (INDEX(Réponses!$B$2:$U$101,MATCH($A2,Réponses!$A$2:$A$101,0),)<>"")* (INDEX(Réponses!$B$2:$U$101,MATCH(E$1,Réponses!$A$2:$A$101,0),)<>"") ) /MAX(1,SUMPRODUCT( (INDEX(Réponses!$B$2:$U$101,MATCH($A2,Réponses!$A$2:$A$101,0),)<>"")* (INDEX(Réponses!$B$2:$U$101,MATCH(E$1,Réponses!$A$2:$A$101,0),)<>"") )),"")} -> 0 | F2: {=IFERROR( SUMPRODUCT( (INDEX(Réponses!$B$2:$U$101,MATCH($A2,Réponses!$A$2:$A$101,0),)=INDEX(Réponses!$B$2:$U$101,MATCH(F$1,Réponses!$A$2:$A$101,0),))* (INDEX(Réponses!$B$2:$U$101,MATCH($A2,Réponses!$A$2:$A$101,0),)<>"")* (INDEX(Réponses!$B$2:$U$101,MATCH(F$1,Réponses!$A$2:$A$101,0),)<>"") ) /MAX(1,SUMPRODUCT( (INDEX(Réponses!$B$2:$U$101,MATCH($A2,Réponses!$A$2:$A$101,0),)<>"")* (INDEX(Réponses!$B$2:$U$101,MATCH(F$1,Réponses!$A$2:$A$101,0),)<>"") )),"")} -> 0 | G2: {=IFERROR( SUMPRODUCT( (INDEX(Réponses!$B$2:$U$101,MATCH($A2,Réponses!$A$2:$A$101,0),)=INDEX(Réponses!$B$2:$U$101,MATCH(G$1,Réponses!$A$2:$A$101,0),))* (INDEX(Réponses!$B$2:$U$101,MATCH($A2,Réponses!$A$2:$A$101,0),)<>"")* (INDEX(Réponses!$B$2:$U$101,MATCH(G$1,Réponses!$A$2:$A$101,0),)<>"") ) /MAX(1,SUMPRODUCT( (INDEX(Réponses!$B$2:$U$101,MATCH($A2,Réponses!$A$2:$A$101,0),)<>"")* (INDEX(Réponses!$B$2:$U$101,MATCH(G$1,Réponses!$A$2:$A$101,0),)<>"") )),"")} -> 0 | H2: {=IFERROR( SUMPRODUCT( (INDEX(Réponses!$B$2:$U$101,MATCH($A2,Réponses!$A$2:$A$101,0),)=INDEX(Réponses!$B$2:$U$101,MATCH(H$1,Réponses!$A$2:$A$101,0),))* (INDEX(Réponses!$B$2:$U$101,MATCH($A2,Réponses!$A$2:$A$101,0),)<>"")* (INDEX(Réponses!$B$2:$U$101,MATCH(H$1,Réponses!$A$2:$A$101,0),)<>"") ) /MAX(1,SUMPRODUCT( (INDEX(Réponses!$B$2:$U$101,MATCH($A2,Réponses!$A$2:$A$101,0),)<>"")* (INDEX(Réponses!$B$2:$U$101,MATCH(H$1,Réponses!$A$2:$A$101,0),)<>"") )),"")} -> 0 | I2: {=IFERROR( SUMPRODUCT( (INDEX(Réponses!$B$2:$U$101,MATCH($A2,Réponses!$A$2:$A$101,0),)=INDEX(Réponses!$B$2:$U$101,MATCH(I$1,Réponses!$A$2:$A$101,0),))* (INDEX(Réponses!$B$2:$U$101,MATCH($A2,Réponses!$A$2:$A$101,0),)<>"")* (INDEX(Réponses!$B$2:$U$101,MATCH(I$1,Réponses!$A$2:$A$101,0),)<>"") ) /MAX(1,SUMPRODUCT( (INDEX(Réponses!$B$2:$U$101,MATCH($A2,Réponses!$A$2:$A$101,0),)<>"")* (INDEX(Réponses!$B$2:$U$101,MATCH(I$1,Réponses!$A$2:$A$101,0),)<>"") )),"")} -> 0.1 | ... CW2: {=IFERROR( SUMPRODUCT( (INDEX(Réponses!$B$2:$U$101,MATCH($A2,Réponses!$A$2:$A$101,0),)=INDEX(Réponses!$B$2:$U$101,MATCH(CW$1,Réponses!$A$2:$A$101,0),))* (INDEX(Réponses!$B$2:$U$101,MATCH($A2,Réponses!$A$2:$A$101,0),)<>"")* (INDEX(Réponses!$B$2:$U$101,MATCH(CW$1,Réponses!$A$2:$A$101,0),)<>"") ) /MAX(1,SUMPRODUCT( (INDEX(Réponses!$B$2:$U$101,MATCH($A2,Réponses!$A$2:$A$101,0),)<>"")* (INDEX(Réponses!$B$2:$U$101,MATCH(CW$1,Réponses!$A$2:$A$101,0),)<>"") )),"")} -> 0
A3: 2 | B3: {=IFERROR( SUMPRODUCT( (INDEX(Réponses!$B$2:$U$101,MATCH($A3,Réponses!$A$2:$A$101,0),)=INDEX(Réponses!$B$2:$U$101,MATCH(B$1,Réponses!$A$2:$A$101,0),))* (INDEX(Réponses!$B$2:$U$101,MATCH($A3,Réponses!$A$2:$A$101,0),)<>"")* (INDEX(Réponses!$B$2:$U$101,MATCH(B$1,Réponses!$A$2:$A$101,0),)<>"") ) /MAX(1,SUMPRODUCT( (INDEX(Réponses!$B$2:$U$101,MATCH($A3,Réponses!$A$2:$A$101,0),)<>"")* (INDEX(Réponses!$B$2:$U$101,MATCH(B$1,Réponses!$A$2:$A$101,0),)<>"") )),"")} -> 0 | C3: {=IFERROR( SUMPRODUCT( (INDEX(Réponses!$B$2:$U$101,MATCH($A3,Réponses!$A$2:$A$101,0),)=INDEX(Réponses!$B$2:$U$101,MATCH(C$1,Réponses!$A$2:$A$101,0),))* (INDEX(Réponses!$B$2:$U$101,MATCH($A3,Réponses!$A$2:$A$101,0),)<>"")* (INDEX(Réponses!$B$2:$U$101,MATCH(C$1,Réponses!$A$2:$A$101,0),)<>"") ) /MAX(1,SUMPRODUCT( (INDEX(Réponses!$B$2:$U$101,MATCH($A3,Réponses!$A$2:$A$101,0),)<>"")* (INDEX(Réponses!$B$2:$U$101,MATCH(C$1,Réponses!$A$2:$A$101,0),)<>"") )),"")} -> 1 | D3: {=IFERROR( SUMPRODUCT( (INDEX(Réponses!$B$2:$U$101,MATCH($A3,Réponses!$A$2:$A$101,0),)=INDEX(Réponses!$B$2:$U$101,MATCH(D$1,Réponses!$A$2:$A$101,0),))* (INDEX(Réponses!$B$2:$U$101,MATCH($A3,Réponses!$A$2:$A$101,0),)<>"")* (INDEX(Réponses!$B$2:$U$101,MATCH(D$1,Réponses!$A$2:$A$101,0),)<>"") ) /MAX(1,SUMPRODUCT( (INDEX(Réponses!$B$2:$U$101,MATCH($A3,Réponses!$A$2:$A$101,0),)<>"")* (INDEX(Réponses!$B$2:$U$101,MATCH(D$1,Réponses!$A$2:$A$101,0),)<>"") )),"")} -> 0 | E3: {=IFERROR( SUMPRODUCT( (INDEX(Réponses!$B$2:$U$101,MATCH($A3,Réponses!$A$2:$A$101,0),)=INDEX(Réponses!$B$2:$U$101,MATCH(E$1,Réponses!$A$2:$A$101,0),))* (INDEX(Réponses!$B$2:$U$101,MATCH($A3,Réponses!$A$2:$A$101,0),)<>"")* (INDEX(Réponses!$B$2:$U$101,MATCH(E$1,Réponses!$A$2:$A$101,0),)<>"") ) /MAX(1,SUMPRODUCT( (INDEX(Réponses!$B$2:$U$101,MATCH($A3,Réponses!$A$2:$A$101,0),)<>"")* (INDEX(Réponses!$B$2:$U$101,MATCH(E$1,Réponses!$A$2:$A$101,0),)<>"") )),"")} -> 0 | F3: {=IFERROR( SUMPRODUCT( (INDEX(Réponses!$B$2:$U$101,MATCH($A3,Réponses!$A$2:$A$101,0),)=INDEX(Réponses!$B$2:$U$101,MATCH(F$1,Réponses!$A$2:$A$101,0),))* (INDEX(Réponses!$B$2:$U$101,MATCH($A3,Réponses!$A$2:$A$101,0),)<>"")* (INDEX(Réponses!$B$2:$U$101,MATCH(F$1,Réponses!$A$2:$A$101,0),)<>"") ) /MAX(1,SUMPRODUCT( (INDEX(Réponses!$B$2:$U$101,MATCH($A3,Réponses!$A$2:$A$101,0),)<>"")* (INDEX(Réponses!$B$2:$U$101,MATCH(F$1,Réponses!$A$2:$A$101,0),)<>"") )),"")} -> 0.65 | G3: {=IFERROR( SUMPRODUCT( (INDEX(Réponses!$B$2:$U$101,MATCH($A3,Réponses!$A$2:$A$101,0),)=INDEX(Réponses!$B$2:$U$101,MATCH(G$1,Réponses!$A$2:$A$101,0),))* (INDEX(Réponses!$B$2:$U$101,MATCH($A3,Réponses!$A$2:$A$101,0),)<>"")* (INDEX(Réponses!$B$2:$U$101,MATCH(G$1,Réponses!$A$2:$A$101,0),)<>"") ) /MAX(1,SUMPRODUCT( (INDEX(Réponses!$B$2:$U$101,MATCH($A3,Réponses!$A$2:$A$101,0),)<>"")* (INDEX(Réponses!$B$2:$U$101,MATCH(G$1,Réponses!$A$2:$A$101,0),)<>"") )),"")} -> 0 | H3: {=IFERROR( SUMPRODUCT( (INDEX(Réponses!$B$2:$U$101,MATCH($A3,Réponses!$A$2:$A$101,0),)=INDEX(Réponses!$B$2:$U$101,MATCH(H$1,Réponses!$A$2:$A$101,0),))* (INDEX(Réponses!$B$2:$U$101,MATCH($A3,Réponses!$A$2:$A$101,0),)<>"")* (INDEX(Réponses!$B$2:$U$101,MATCH(H$1,Réponses!$A$2:$A$101,0),)<>"") ) /MAX(1,SUMPRODUCT( (INDEX(Réponses!$B$2:$U$101,MATCH($A3,Réponses!$A$2:$A$101,0),)<>"")* (INDEX(Réponses!$B$2:$U$101,MATCH(H$1,Réponses!$A$2:$A$101,0),)<>"") )),"")} -> 0 | I3: {=IFERROR( SUMPRODUCT( (INDEX(Réponses!$B$2:$U$101,MATCH($A3,Réponses!$A$2:$A$101,0),)=INDEX(Réponses!$B$2:$U$101,MATCH(I$1,Réponses!$A$2:$A$101,0),))* (INDEX(Réponses!$B$2:$U$101,MATCH($A3,Réponses!$A$2:$A$101,0),)<>"")* (INDEX(Réponses!$B$2:$U$101,MATCH(I$1,Réponses!$A$2:$A$101,0),)<>"") ) /MAX(1,SUMPRODUCT( (INDEX(Réponses!$B$2:$U$101,MATCH($A3,Réponses!$A$2:$A$101,0),)<>"")* (INDEX(Réponses!$B$2:$U$101,MATCH(I$1,Réponses!$A$2:$A$101,0),)<>"") )),"")} -> 0.05 | ... CW3: {=IFERROR( SUMPRODUCT( (INDEX(Réponses!$B$2:$U$101,MATCH($A3,Réponses!$A$2:$A$101,0),)=INDEX(Réponses!$B$2:$U$101,MATCH(CW$1,Réponses!$A$2:$A$101,0),))* (INDEX(Réponses!$B$2:$U$101,MATCH($A3,Réponses!$A$2:$A$101,0),)<>"")* (INDEX(Réponses!$B$2:$U$101,MATCH(CW$1,Réponses!$A$2:$A$101,0),)<>"") ) /MAX(1,SUMPRODUCT( (INDEX(Réponses!$B$2:$U$101,MATCH($A3,Réponses!$A$2:$A$101,0),)<>"")* (INDEX(Réponses!$B$2:$U$101,MATCH(CW$1,Réponses!$A$2:$A$101,0),)<>"") )),"")} -> 0
A4: 3 | B4: {=IFERROR( SUMPRODUCT( (INDEX(Réponses!$B$2:$U$101,MATCH($A4,Réponses!$A$2:$A$101,0),)=INDEX(Réponses!$B$2:$U$101,MATCH(B$1,Réponses!$A$2:$A$101,0),))* (INDEX(Réponses!$B$2:$U$101,MATCH($A4,Réponses!$A$2:$A$101,0),)<>"")* (INDEX(Réponses!$B$2:$U$101,MATCH(B$1,Réponses!$A$2:$A$101,0),)<>"") ) /MAX(1,SUMPRODUCT( (INDEX(Réponses!$B$2:$U$101,MATCH($A4,Réponses!$A$2:$A$101,0),)<>"")* (INDEX(Réponses!$B$2:$U$101,MATCH(B$1,Réponses!$A$2:$A$101,0),)<>"") )),"")} -> 0 | C4: {=IFERROR( SUMPRODUCT( (INDEX(Réponses!$B$2:$U$101,MATCH($A4,Réponses!$A$2:$A$101,0),)=INDEX(Réponses!$B$2:$U$101,MATCH(C$1,Réponses!$A$2:$A$101,0),))* (INDEX(Réponses!$B$2:$U$101,MATCH($A4,Réponses!$A$2:$A$101,0),)<>"")* (INDEX(Réponses!$B$2:$U$101,MATCH(C$1,Réponses!$A$2:$A$101,0),)<>"") ) /MAX(1,SUMPRODUCT( (INDEX(Réponses!$B$2:$U$101,MATCH($A4,Réponses!$A$2:$A$101,0),)<>"")* (INDEX(Réponses!$B$2:$U$101,MATCH(C$1,Réponses!$A$2:$A$101,0),)<>"") )),"")} -> 0 | D4: {=IFERROR( SUMPRODUCT( (INDEX(Réponses!$B$2:$U$101,MATCH($A4,Réponses!$A$2:$A$101,0),)=INDEX(Réponses!$B$2:$U$101,MATCH(D$1,Réponses!$A$2:$A$101,0),))* (INDEX(Réponses!$B$2:$U$101,MATCH($A4,Réponses!$A$2:$A$101,0),)<>"")* (INDEX(Réponses!$B$2:$U$101,MATCH(D$1,Réponses!$A$2:$A$101,0),)<>"") ) /MAX(1,SUMPRODUCT( (INDEX(Réponses!$B$2:$U$101,MATCH($A4,Réponses!$A$2:$A$101,0),)<>"")* (INDEX(Réponses!$B$2:$U$101,MATCH(D$1,Réponses!$A$2:$A$101,0),)<>"") )),"")} -> 1 | E4: {=IFERROR( SUMPRODUCT( (INDEX(Réponses!$B$2:$U$101,MATCH($A4,Réponses!$A$2:$A$101,0),)=INDEX(Réponses!$B$2:$U$101,MATCH(E$1,Réponses!$A$2:$A$101,0),))* (INDEX(Réponses!$B$2:$U$101,MATCH($A4,Réponses!$A$2:$A$101,0),)<>"")* (INDEX(Réponses!$B$2:$U$101,MATCH(E$1,Réponses!$A$2:$A$101,0),)<>"") ) /MAX(1,SUMPRODUCT( (INDEX(Réponses!$B$2:$U$101,MATCH($A4,Réponses!$A$2:$A$101,0),)<>"")* (INDEX(Réponses!$B$2:$U$101,MATCH(E$1,Réponses!$A$2:$A$101,0),)<>"") )),"")} -> 0 | F4: {=IFERROR( SUMPRODUCT( (INDEX(Réponses!$B$2:$U$101,MATCH($A4,Réponses!$A$2:$A$101,0),)=INDEX(Réponses!$B$2:$U$101,MATCH(F$1,Réponses!$A$2:$A$101,0),))* (INDEX(Réponses!$B$2:$U$101,MATCH($A4,Réponses!$A$2:$A$101,0),)<>"")* (INDEX(Réponses!$B$2:$U$101,MATCH(F$1,Réponses!$A$2:$A$101,0),)<>"") ) /MAX(1,SUMPRODUCT( (INDEX(Réponses!$B$2:$U$101,MATCH($A4,Réponses!$A$2:$A$101,0),)<>"")* (INDEX(Réponses!$B$2:$U$101,MATCH(F$1,Réponses!$A$2:$A$101,0),)<>"") )),"")} -> 0 | G4: {=IFERROR( SUMPRODUCT( (INDEX(Réponses!$B$2:$U$101,MATCH($A4,Réponses!$A$2:$A$101,0),)=INDEX(Réponses!$B$2:$U$101,MATCH(G$1,Réponses!$A$2:$A$101,0),))* (INDEX(Réponses!$B$2:$U$101,MATCH($A4,Réponses!$A$2:$A$101,0),)<>"")* (INDEX(Réponses!$B$2:$U$101,MATCH(G$1,Réponses!$A$2:$A$101,0),)<>"") ) /MAX(1,SUMPRODUCT( (INDEX(Réponses!$B$2:$U$101,MATCH($A4,Réponses!$A$2:$A$101,0),)<>"")* (INDEX(Réponses!$B$2:$U$101,MATCH(G$1,Réponses!$A$2:$A$101,0),)<>"") )),"")} -> 0 | H4: {=IFERROR( SUMPRODUCT( (INDEX(Réponses!$B$2:$U$101,MATCH($A4,Réponses!$A$2:$A$101,0),)=INDEX(Réponses!$B$2:$U$101,MATCH(H$1,Réponses!$A$2:$A$101,0),))* (INDEX(Réponses!$B$2:$U$101,MATCH($A4,Réponses!$A$2:$A$101,0),)<>"")* (INDEX(Réponses!$B$2:$U$101,MATCH(H$1,Réponses!$A$2:$A$101,0),)<>"") ) /MAX(1,SUMPRODUCT( (INDEX(Réponses!$B$2:$U$101,MATCH($A4,Réponses!$A$2:$A$101,0),)<>"")* (INDEX(Réponses!$B$2:$U$101,MATCH(H$1,Réponses!$A$2:$A$101,0),)<>"") )),"")} -> 0 | I4: {=IFERROR( SUMPRODUCT( (INDEX(Réponses!$B$2:$U$101,MATCH($A4,Réponses!$A$2:$A$101,0),)=INDEX(Réponses!$B$2:$U$101,MATCH(I$1,Réponses!$A$2:$A$101,0),))* (INDEX(Réponses!$B$2:$U$101,MATCH($A4,Réponses!$A$2:$A$101,0),)<>"")* (INDEX(Réponses!$B$2:$U$101,MATCH(I$1,Réponses!$A$2:$A$101,0),)<>"") ) /MAX(1,SUMPRODUCT( (INDEX(Réponses!$B$2:$U$101,MATCH($A4,Réponses!$A$2:$A$101,0),)<>"")* (INDEX(Réponses!$B$2:$U$101,MATCH(I$1,Réponses!$A$2:$A$101,0),)<>"") )),"")} -> 0 | ... CW4: {=IFERROR( SUMPRODUCT( (INDEX(Réponses!$B$2:$U$101,MATCH($A4,Réponses!$A$2:$A$101,0),)=INDEX(Réponses!$B$2:$U$101,MATCH(CW$1,Réponses!$A$2:$A$101,0),))* (INDEX(Réponses!$B$2:$U$101,MATCH($A4,Réponses!$A$2:$A$101,0),)<>"")* (INDEX(Réponses!$B$2:$U$101,MATCH(CW$1,Réponses!$A$2:$A$101,0),)<>"") ) /MAX(1,SUMPRODUCT( (INDEX(Réponses!$B$2:$U$101,MATCH($A4,Réponses!$A$2:$A$101,0),)<>"")* (INDEX(Réponses!$B$2:$U$101,MATCH(CW$1,Réponses!$A$2:$A$101,0),)<>"") )),"")} -> 0
A5: 4 | B5: {=IFERROR( SUMPRODUCT( (INDEX(Réponses!$B$2:$U$101,MATCH($A5,Réponses!$A$2:$A$101,0),)=INDEX(Réponses!$B$2:$U$101,MATCH(B$1,Réponses!$A$2:$A$101,0),))* (INDEX(Réponses!$B$2:$U$101,MATCH($A5,Réponses!$A$2:$A$101,0),)<>"")* (INDEX(Réponses!$B$2:$U$101,MATCH(B$1,Réponses!$A$2:$A$101,0),)<>"") ) /MAX(1,SUMPRODUCT( (INDEX(Réponses!$B$2:$U$101,MATCH($A5,Réponses!$A$2:$A$101,0),)<>"")* (INDEX(Réponses!$B$2:$U$101,MATCH(B$1,Réponses!$A$2:$A$101,0),)<>"") )),"")} -> 0 | C5: {=IFERROR( SUMPRODUCT( (INDEX(Réponses!$B$2:$U$101,MATCH($A5,Réponses!$A$2:$A$101,0),)=INDEX(Réponses!$B$2:$U$101,MATCH(C$1,Réponses!$A$2:$A$101,0),))* (INDEX(Réponses!$B$2:$U$101,MATCH($A5,Réponses!$A$2:$A$101,0),)<>"")* (INDEX(Réponses!$B$2:$U$101,MATCH(C$1,Réponses!$A$2:$A$101,0),)<>"") ) /MAX(1,SUMPRODUCT( (INDEX(Réponses!$B$2:$U$101,MATCH($A5,Réponses!$A$2:$A$101,0),)<>"")* (INDEX(Réponses!$B$2:$U$101,MATCH(C$1,Réponses!$A$2:$A$101,0),)<>"") )),"")} -> 0 | D5: {=IFERROR( SUMPRODUCT( (INDEX(Réponses!$B$2:$U$101,MATCH($A5,Réponses!$A$2:$A$101,0),)=INDEX(Réponses!$B$2:$U$101,MATCH(D$1,Réponses!$A$2:$A$101,0),))* (INDEX(Réponses!$B$2:$U$101,MATCH($A5,Réponses!$A$2:$A$101,0),)<>"")* (INDEX(Réponses!$B$2:$U$101,MATCH(D$1,Réponses!$A$2:$A$101,0),)<>"") ) /MAX(1,SUMPRODUCT( (INDEX(Réponses!$B$2:$U$101,MATCH($A5,Réponses!$A$2:$A$101,0),)<>"")* (INDEX(Réponses!$B$2:$U$101,MATCH(D$1,Réponses!$A$2:$A$101,0),)<>"") )),"")} -> 0 | E5: {=IFERROR( SUMPRODUCT( (INDEX(Réponses!$B$2:$U$101,MATCH($A5,Réponses!$A$2:$A$101,0),)=INDEX(Réponses!$B$2:$U$101,MATCH(E$1,Réponses!$A$2:$A$101,0),))* (INDEX(Réponses!$B$2:$U$101,MATCH($A5,Réponses!$A$2:$A$101,0),)<>"")* (INDEX(Réponses!$B$2:$U$101,MATCH(E$1,Réponses!$A$2:$A$101,0),)<>"") ) /MAX(1,SUMPRODUCT( (INDEX(Réponses!$B$2:$U$101,MATCH($A5,Réponses!$A$2:$A$101,0),)<>"")* (INDEX(Réponses!$B$2:$U$101,MATCH(E$1,Réponses!$A$2:$A$101,0),)<>"") )),"")} -> 1 | F5: {=IFERROR( SUMPRODUCT( (INDEX(Réponses!$B$2:$U$101,MATCH($A5,Réponses!$A$2:$A$101,0),)=INDEX(Réponses!$B$2:$U$101,MATCH(F$1,Réponses!$A$2:$A$101,0),))* (INDEX(Réponses!$B$2:$U$101,MATCH($A5,Réponses!$A$2:$A$101,0),)<>"")* (INDEX(Réponses!$B$2:$U$101,MATCH(F$1,Réponses!$A$2:$A$101,0),)<>"") ) /MAX(1,SUMPRODUCT( (INDEX(Réponses!$B$2:$U$101,MATCH($A5,Réponses!$A$2:$A$101,0),)<>"")* (INDEX(Réponses!$B$2:$U$101,MATCH(F$1,Réponses!$A$2:$A$101,0),)<>"") )),"")} -> 0 | G5: {=IFERROR( SUMPRODUCT( (INDEX(Réponses!$B$2:$U$101,MATCH($A5,Réponses!$A$2:$A$101,0),)=INDEX(Réponses!$B$2:$U$101,MATCH(G$1,Réponses!$A$2:$A$101,0),))* (INDEX(Réponses!$B$2:$U$101,MATCH($A5,Réponses!$A$2:$A$101,0),)<>"")* (INDEX(Réponses!$B$2:$U$101,MATCH(G$1,Réponses!$A$2:$A$101,0),)<>"") ) /MAX(1,SUMPRODUCT( (INDEX(Réponses!$B$2:$U$101,MATCH($A5,Réponses!$A$2:$A$101,0),)<>"")* (INDEX(Réponses!$B$2:$U$101,MATCH(G$1,Réponses!$A$2:$A$101,0),)<>"") )),"")} -> 0 | H5: {=IFERROR( SUMPRODUCT( (INDEX(Réponses!$B$2:$U$101,MATCH($A5,Réponses!$A$2:$A$101,0),)=INDEX(Réponses!$B$2:$U$101,MATCH(H$1,Réponses!$A$2:$A$101,0),))* (INDEX(Réponses!$B$2:$U$101,MATCH($A5,Réponses!$A$2:$A$101,0),)<>"")* (INDEX(Réponses!$B$2:$U$101,MATCH(H$1,Réponses!$A$2:$A$101,0),)<>"") ) /MAX(1,SUMPRODUCT( (INDEX(Réponses!$B$2:$U$101,MATCH($A5,Réponses!$A$2:$A$101,0),)<>"")* (INDEX(Réponses!$B$2:$U$101,MATCH(H$1,Réponses!$A$2:$A$101,0),)<>"") )),"")} -> 0 | I5: {=IFERROR( SUMPRODUCT( (INDEX(Réponses!$B$2:$U$101,MATCH($A5,Réponses!$A$2:$A$101,0),)=INDEX(Réponses!$B$2:$U$101,MATCH(I$1,Réponses!$A$2:$A$101,0),))* (INDEX(Réponses!$B$2:$U$101,MATCH($A5,Réponses!$A$2:$A$101,0),)<>"")* (INDEX(Réponses!$B$2:$U$101,MATCH(I$1,Réponses!$A$2:$A$101,0),)<>"") ) /MAX(1,SUMPRODUCT( (INDEX(Réponses!$B$2:$U$101,MATCH($A5,Réponses!$A$2:$A$101,0),)<>"")* (INDEX(Réponses!$B$2:$U$101,MATCH(I$1,Réponses!$A$2:$A$101,0),)<>"") )),"")} -> 0 | ... CW5: {=IFERROR( SUMPRODUCT( (INDEX(Réponses!$B$2:$U$101,MATCH($A5,Réponses!$A$2:$A$101,0),)=INDEX(Réponses!$B$2:$U$101,MATCH(CW$1,Réponses!$A$2:$A$101,0),))* (INDEX(Réponses!$B$2:$U$101,MATCH($A5,Réponses!$A$2:$A$101,0),)<>"")* (INDEX(Réponses!$B$2:$U$101,MATCH(CW$1,Réponses!$A$2:$A$101,0),)<>"") ) /MAX(1,SUMPRODUCT( (INDEX(Réponses!$B$2:$U$101,MATCH($A5,Réponses!$A$2:$A$101,0),)<>"")* (INDEX(Réponses!$B$2:$U$101,MATCH(CW$1,Réponses!$A$2:$A$101,0),)<>"") )),"")} -> 0
A6: 5 | B6: {=IFERROR( SUMPRODUCT( (INDEX(Réponses!$B$2:$U$101,MATCH($A6,Réponses!$A$2:$A$101,0),)=INDEX(Réponses!$B$2:$U$101,MATCH(B$1,Réponses!$A$2:$A$101,0),))* (INDEX(Réponses!$B$2:$U$101,MATCH($A6,Réponses!$A$2:$A$101,0),)<>"")* (INDEX(Réponses!$B$2:$U$101,MATCH(B$1,Réponses!$A$2:$A$101,0),)<>"") ) /MAX(1,SUMPRODUCT( (INDEX(Réponses!$B$2:$U$101,MATCH($A6,Réponses!$A$2:$A$101,0),)<>"")* (INDEX(Réponses!$B$2:$U$101,MATCH(B$1,Réponses!$A$2:$A$101,0),)<>"") )),"")} -> 0 | C6: {=IFERROR( SUMPRODUCT( (INDEX(Réponses!$B$2:$U$101,MATCH($A6,Réponses!$A$2:$A$101,0),)=INDEX(Réponses!$B$2:$U$101,MATCH(C$1,Réponses!$A$2:$A$101,0),))* (INDEX(Réponses!$B$2:$U$101,MATCH($A6,Réponses!$A$2:$A$101,0),)<>"")* (INDEX(Réponses!$B$2:$U$101,MATCH(C$1,Réponses!$A$2:$A$101,0),)<>"") ) /MAX(1,SUMPRODUCT( (INDEX(Réponses!$B$2:$U$101,MATCH($A6,Réponses!$A$2:$A$101,0),)<>"")* (INDEX(Réponses!$B$2:$U$101,MATCH(C$1,Réponses!$A$2:$A$101,0),)<>"") )),"")} -> 0.65 | D6: {=IFERROR( SUMPRODUCT( (INDEX(Réponses!$B$2:$U$101,MATCH($A6,Réponses!$A$2:$A$101,0),)=INDEX(Réponses!$B$2:$U$101,MATCH(D$1,Réponses!$A$2:$A$101,0),))* (INDEX(Réponses!$B$2:$U$101,MATCH($A6,Réponses!$A$2:$A$101,0),)<>"")* (INDEX(Réponses!$B$2:$U$101,MATCH(D$1,Réponses!$A$2:$A$101,0),)<>"") ) /MAX(1,SUMPRODUCT( (INDEX(Réponses!$B$2:$U$101,MATCH($A6,Réponses!$A$2:$A$101,0),)<>"")* (INDEX(Réponses!$B$2:$U$101,MATCH(D$1,Réponses!$A$2:$A$101,0),)<>"") )),"")} -> 0 | E6: {=IFERROR( SUMPRODUCT( (INDEX(Réponses!$B$2:$U$101,MATCH($A6,Réponses!$A$2:$A$101,0),)=INDEX(Réponses!$B$2:$U$101,MATCH(E$1,Réponses!$A$2:$A$101,0),))* (INDEX(Réponses!$B$2:$U$101,MATCH($A6,Réponses!$A$2:$A$101,0),)<>"")* (INDEX(Réponses!$B$2:$U$101,MATCH(E$1,Réponses!$A$2:$A$101,0),)<>"") ) /MAX(1,SUMPRODUCT( (INDEX(Réponses!$B$2:$U$101,MATCH($A6,Réponses!$A$2:$A$101,0),)<>"")* (INDEX(Réponses!$B$2:$U$101,MATCH(E$1,Réponses!$A$2:$A$101,0),)<>"") )),"")} -> 0 | F6: {=IFERROR( SUMPRODUCT( (INDEX(Réponses!$B$2:$U$101,MATCH($A6,Réponses!$A$2:$A$101,0),)=INDEX(Réponses!$B$2:$U$101,MATCH(F$1,Réponses!$A$2:$A$101,0),))* (INDEX(Réponses!$B$2:$U$101,MATCH($A6,Réponses!$A$2:$A$101,0),)<>"")* (INDEX(Réponses!$B$2:$U$101,MATCH(F$1,Réponses!$A$2:$A$101,0),)<>"") ) /MAX(1,SUMPRODUCT( (INDEX(Réponses!$B$2:$U$101,MATCH($A6,Réponses!$A$2:$A$101,0),)<>"")* (INDEX(Réponses!$B$2:$U$101,MATCH(F$1,Réponses!$A$2:$A$101,0),)<>"") )),"")} -> 1 | G6: {=IFERROR( SUMPRODUCT( (INDEX(Réponses!$B$2:$U$101,MATCH($A6,Réponses!$A$2:$A$101,0),)=INDEX(Réponses!$B$2:$U$101,MATCH(G$1,Réponses!$A$2:$A$101,0),))* (INDEX(Réponses!$B$2:$U$101,MATCH($A6,Réponses!$A$2:$A$101,0),)<>"")* (INDEX(Réponses!$B$2:$U$101,MATCH(G$1,Réponses!$A$2:$A$101,0),)<>"") ) /MAX(1,SUMPRODUCT( (INDEX(Réponses!$B$2:$U$101,MATCH($A6,Réponses!$A$2:$A$101,0),)<>"")* (INDEX(Réponses!$B$2:$U$101,MATCH(G$1,Réponses!$A$2:$A$101,0),)<>"") )),"")} -> 0 | H6: {=IFERROR( SUMPRODUCT( (INDEX(Réponses!$B$2:$U$101,MATCH($A6,Réponses!$A$2:$A$101,0),)=INDEX(Réponses!$B$2:$U$101,MATCH(H$1,Réponses!$A$2:$A$101,0),))* (INDEX(Réponses!$B$2:$U$101,MATCH($A6,Réponses!$A$2:$A$101,0),)<>"")* (INDEX(Réponses!$B$2:$U$101,MATCH(H$1,Réponses!$A$2:$A$101,0),)<>"") ) /MAX(1,SUMPRODUCT( (INDEX(Réponses!$B$2:$U$101,MATCH($A6,Réponses!$A$2:$A$101,0),)<>"")* (INDEX(Réponses!$B$2:$U$101,MATCH(H$1,Réponses!$A$2:$A$101,0),)<>"") )),"")} -> 0 | I6: {=IFERROR( SUMPRODUCT( (INDEX(Réponses!$B$2:$U$101,MATCH($A6,Réponses!$A$2:$A$101,0),)=INDEX(Réponses!$B$2:$U$101,MATCH(I$1,Réponses!$A$2:$A$101,0),))* (INDEX(Réponses!$B$2:$U$101,MATCH($A6,Réponses!$A$2:$A$101,0),)<>"")* (INDEX(Réponses!$B$2:$U$101,MATCH(I$1,Réponses!$A$2:$A$101,0),)<>"") ) /MAX(1,SUMPRODUCT( (INDEX(Réponses!$B$2:$U$101,MATCH($A6,Réponses!$A$2:$A$101,0),)<>"")* (INDEX(Réponses!$B$2:$U$101,MATCH(I$1,Réponses!$A$2:$A$101,0),)<>"") )),"")} -> 0 | ... CW6: {=IFERROR( SUMPRODUCT( (INDEX(Réponses!$B$2:$U$101,MATCH($A6,Réponses!$A$2:$A$101,0),)=INDEX(Réponses!$B$2:$U$101,MATCH(CW$1,Réponses!$A$2:$A$101,0),))* (INDEX(Réponses!$B$2:$U$101,MATCH($A6,Réponses!$A$2:$A$101,0),)<>"")* (INDEX(Réponses!$B$2:$U$101,MATCH(CW$1,Réponses!$A$2:$A$101,0),)<>"") ) /MAX(1,SUMPRODUCT( (INDEX(Réponses!$B$2:$U$101,MATCH($A6,Réponses!$A$2:$A$101,0),)<>"")* (INDEX(Réponses!$B$2:$U$101,MATCH(CW$1,Réponses!$A$2:$A$101,0),)<>"") )),"")} -> 0
A7: 6 | B7: {=IFERROR( SUMPRODUCT( (INDEX(Réponses!$B$2:$U$101,MATCH($A7,Réponses!$A$2:$A$101,0),)=INDEX(Réponses!$B$2:$U$101,MATCH(B$1,Réponses!$A$2:$A$101,0),))* (INDEX(Réponses!$B$2:$U$101,MATCH($A7,Réponses!$A$2:$A$101,0),)<>"")* (INDEX(Réponses!$B$2:$U$101,MATCH(B$1,Réponses!$A$2:$A$101,0),)<>"") ) /MAX(1,SUMPRODUCT( (INDEX(Réponses!$B$2:$U$101,MATCH($A7,Réponses!$A$2:$A$101,0),)<>"")* (INDEX(Réponses!$B$2:$U$101,MATCH(B$1,Réponses!$A$2:$A$101,0),)<>"") )),"")} -> 0 | C7: {=IFERROR( SUMPRODUCT( (INDEX(Réponses!$B$2:$U$101,MATCH($A7,Réponses!$A$2:$A$101,0),)=INDEX(Réponses!$B$2:$U$101,MATCH(C$1,Réponses!$A$2:$A$101,0),))* (INDEX(Réponses!$B$2:$U$101,MATCH($A7,Réponses!$A$2:$A$101,0),)<>"")* (INDEX(Réponses!$B$2:$U$101,MATCH(C$1,Réponses!$A$2:$A$101,0),)<>"") ) /MAX(1,SUMPRODUCT( (INDEX(Réponses!$B$2:$U$101,MATCH($A7,Réponses!$A$2:$A$101,0),)<>"")* (INDEX(Réponses!$B$2:$U$101,MATCH(C$1,Réponses!$A$2:$A$101,0),)<>"") )),"")} -> 0 | D7: {=IFERROR( SUMPRODUCT( (INDEX(Réponses!$B$2:$U$101,MATCH($A7,Réponses!$A$2:$A$101,0),)=INDEX(Réponses!$B$2:$U$101,MATCH(D$1,Réponses!$A$2:$A$101,0),))* (INDEX(Réponses!$B$2:$U$101,MATCH($A7,Réponses!$A$2:$A$101,0),)<>"")* (INDEX(Réponses!$B$2:$U$101,MATCH(D$1,Réponses!$A$2:$A$101,0),)<>"") ) /MAX(1,SUMPRODUCT( (INDEX(Réponses!$B$2:$U$101,MATCH($A7,Réponses!$A$2:$A$101,0),)<>"")* (INDEX(Réponses!$B$2:$U$101,MATCH(D$1,Réponses!$A$2:$A$101,0),)<>"") )),"")} -> 0 | E7: {=IFERROR( SUMPRODUCT( (INDEX(Réponses!$B$2:$U$101,MATCH($A7,Réponses!$A$2:$A$101,0),)=INDEX(Réponses!$B$2:$U$101,MATCH(E$1,Réponses!$A$2:$A$101,0),))* (INDEX(Réponses!$B$2:$U$101,MATCH($A7,Réponses!$A$2:$A$101,0),)<>"")* (INDEX(Réponses!$B$2:$U$101,MATCH(E$1,Réponses!$A$2:$A$101,0),)<>"") ) /MAX(1,SUMPRODUCT( (INDEX(Réponses!$B$2:$U$101,MATCH($A7,Réponses!$A$2:$A$101,0),)<>"")* (INDEX(Réponses!$B$2:$U$101,MATCH(E$1,Réponses!$A$2:$A$101,0),)<>"") )),"")} -> 0 | F7: {=IFERROR( SUMPRODUCT( (INDEX(Réponses!$B$2:$U$101,MATCH($A7,Réponses!$A$2:$A$101,0),)=INDEX(Réponses!$B$2:$U$101,MATCH(F$1,Réponses!$A$2:$A$101,0),))* (INDEX(Réponses!$B$2:$U$101,MATCH($A7,Réponses!$A$2:$A$101,0),)<>"")* (INDEX(Réponses!$B$2:$U$101,MATCH(F$1,Réponses!$A$2:$A$101,0),)<>"") ) /MAX(1,SUMPRODUCT( (INDEX(Réponses!$B$2:$U$101,MATCH($A7,Réponses!$A$2:$A$101,0),)<>"")* (INDEX(Réponses!$B$2:$U$101,MATCH(F$1,Réponses!$A$2:$A$101,0),)<>"") )),"")} -> 0 | G7: {=IFERROR( SUMPRODUCT( (INDEX(Réponses!$B$2:$U$101,MATCH($A7,Réponses!$A$2:$A$101,0),)=INDEX(Réponses!$B$2:$U$101,MATCH(G$1,Réponses!$A$2:$A$101,0),))* (INDEX(Réponses!$B$2:$U$101,MATCH($A7,Réponses!$A$2:$A$101,0),)<>"")* (INDEX(Réponses!$B$2:$U$101,MATCH(G$1,Réponses!$A$2:$A$101,0),)<>"") ) /MAX(1,SUMPRODUCT( (INDEX(Réponses!$B$2:$U$101,MATCH($A7,Réponses!$A$2:$A$101,0),)<>"")* (INDEX(Réponses!$B$2:$U$101,MATCH(G$1,Réponses!$A$2:$A$101,0),)<>"") )),"")} -> 1 | H7: {=IFERROR( SUMPRODUCT( (INDEX(Réponses!$B$2:$U$101,MATCH($A7,Réponses!$A$2:$A$101,0),)=INDEX(Réponses!$B$2:$U$101,MATCH(H$1,Réponses!$A$2:$A$101,0),))* (INDEX(Réponses!$B$2:$U$101,MATCH($A7,Réponses!$A$2:$A$101,0),)<>"")* (INDEX(Réponses!$B$2:$U$101,MATCH(H$1,Réponses!$A$2:$A$101,0),)<>"") ) /MAX(1,SUMPRODUCT( (INDEX(Réponses!$B$2:$U$101,MATCH($A7,Réponses!$A$2:$A$101,0),)<>"")* (INDEX(Réponses!$B$2:$U$101,MATCH(H$1,Réponses!$A$2:$A$101,0),)<>"") )),"")} -> 0 | I7: {=IFERROR( SUMPRODUCT( (INDEX(Réponses!$B$2:$U$101,MATCH($A7,Réponses!$A$2:$A$101,0),)=INDEX(Réponses!$B$2:$U$101,MATCH(I$1,Réponses!$A$2:$A$101,0),))* (INDEX(Réponses!$B$2:$U$101,MATCH($A7,Réponses!$A$2:$A$101,0),)<>"")* (INDEX(Réponses!$B$2:$U$101,MATCH(I$1,Réponses!$A$2:$A$101,0),)<>"") ) /MAX(1,SUMPRODUCT( (INDEX(Réponses!$B$2:$U$101,MATCH($A7,Réponses!$A$2:$A$101,0),)<>"")* (INDEX(Réponses!$B$2:$U$101,MATCH(I$1,Réponses!$A$2:$A$101,0),)<>"") )),"")} -> 0 | ... CW7: {=IFERROR( SUMPRODUCT( (INDEX(Réponses!$B$2:$U$101,MATCH($A7,Réponses!$A$2:$A$101,0),)=INDEX(Réponses!$B$2:$U$101,MATCH(CW$1,Réponses!$A$2:$A$101,0),))* (INDEX(Réponses!$B$2:$U$101,MATCH($A7,Réponses!$A$2:$A$101,0),)<>"")* (INDEX(Réponses!$B$2:$U$101,MATCH(CW$1,Réponses!$A$2:$A$101,0),)<>"") ) /MAX(1,SUMPRODUCT( (INDEX(Réponses!$B$2:$U$101,MATCH($A7,Réponses!$A$2:$A$101,0),)<>"")* (INDEX(Réponses!$B$2:$U$101,MATCH(CW$1,Réponses!$A$2:$A$101,0),)<>"") )),"")} -> 0
A8: 7 | B8: {=IFERROR( SUMPRODUCT( (INDEX(Réponses!$B$2:$U$101,MATCH($A8,Réponses!$A$2:$A$101,0),)=INDEX(Réponses!$B$2:$U$101,MATCH(B$1,Réponses!$A$2:$A$101,0),))* (INDEX(Réponses!$B$2:$U$101,MATCH($A8,Réponses!$A$2:$A$101,0),)<>"")* (INDEX(Réponses!$B$2:$U$101,MATCH(B$1,Réponses!$A$2:$A$101,0),)<>"") ) /MAX(1,SUMPRODUCT( (INDEX(Réponses!$B$2:$U$101,MATCH($A8,Réponses!$A$2:$A$101,0),)<>"")* (INDEX(Réponses!$B$2:$U$101,MATCH(B$1,Réponses!$A$2:$A$101,0),)<>"") )),"")} -> 0 | C8: {=IFERROR( SUMPRODUCT( (INDEX(Réponses!$B$2:$U$101,MATCH($A8,Réponses!$A$2:$A$101,0),)=INDEX(Réponses!$B$2:$U$101,MATCH(C$1,Réponses!$A$2:$A$101,0),))* (INDEX(Réponses!$B$2:$U$101,MATCH($A8,Réponses!$A$2:$A$101,0),)<>"")* (INDEX(Réponses!$B$2:$U$101,MATCH(C$1,Réponses!$A$2:$A$101,0),)<>"") ) /MAX(1,SUMPRODUCT( (INDEX(Réponses!$B$2:$U$101,MATCH($A8,Réponses!$A$2:$A$101,0),)<>"")* (INDEX(Réponses!$B$2:$U$101,MATCH(C$1,Réponses!$A$2:$A$101,0),)<>"") )),"")} -> 0 | D8: {=IFERROR( SUMPRODUCT( (INDEX(Réponses!$B$2:$U$101,MATCH($A8,Réponses!$A$2:$A$101,0),)=INDEX(Réponses!$B$2:$U$101,MATCH(D$1,Réponses!$A$2:$A$101,0),))* (INDEX(Réponses!$B$2:$U$101,MATCH($A8,Réponses!$A$2:$A$101,0),)<>"")* (INDEX(Réponses!$B$2:$U$101,MATCH(D$1,Réponses!$A$2:$A$101,0),)<>"") ) /MAX(1,SUMPRODUCT( (INDEX(Réponses!$B$2:$U$101,MATCH($A8,Réponses!$A$2:$A$101,0),)<>"")* (INDEX(Réponses!$B$2:$U$101,MATCH(D$1,Réponses!$A$2:$A$101,0),)<>"") )),"")} -> 0 | E8: {=IFERROR( SUMPRODUCT( (INDEX(Réponses!$B$2:$U$101,MATCH($A8,Réponses!$A$2:$A$101,0),)=INDEX(Réponses!$B$2:$U$101,MATCH(E$1,Réponses!$A$2:$A$101,0),))* (INDEX(Réponses!$B$2:$U$101,MATCH($A8,Réponses!$A$2:$A$101,0),)<>"")* (INDEX(Réponses!$B$2:$U$101,MATCH(E$1,Réponses!$A$2:$A$101,0),)<>"") ) /MAX(1,SUMPRODUCT( (INDEX(Réponses!$B$2:$U$101,MATCH($A8,Réponses!$A$2:$A$101,0),)<>"")* (INDEX(Réponses!$B$2:$U$101,MATCH(E$1,Réponses!$A$2:$A$101,0),)<>"") )),"")} -> 0 | F8: {=IFERROR( SUMPRODUCT( (INDEX(Réponses!$B$2:$U$101,MATCH($A8,Réponses!$A$2:$A$101,0),)=INDEX(Réponses!$B$2:$U$101,MATCH(F$1,Réponses!$A$2:$A$101,0),))* (INDEX(Réponses!$B$2:$U$101,MATCH($A8,Réponses!$A$2:$A$101,0),)<>"")* (INDEX(Réponses!$B$2:$U$101,MATCH(F$1,Réponses!$A$2:$A$101,0),)<>"") ) /MAX(1,SUMPRODUCT( (INDEX(Réponses!$B$2:$U$101,MATCH($A8,Réponses!$A$2:$A$101,0),)<>"")* (INDEX(Réponses!$B$2:$U$101,MATCH(F$1,Réponses!$A$2:$A$101,0),)<>"") )),"")} -> 0 | G8: {=IFERROR( SUMPRODUCT( (INDEX(Réponses!$B$2:$U$101,MATCH($A8,Réponses!$A$2:$A$101,0),)=INDEX(Réponses!$B$2:$U$101,MATCH(G$1,Réponses!$A$2:$A$101,0),))* (INDEX(Réponses!$B$2:$U$101,MATCH($A8,Réponses!$A$2:$A$101,0),)<>"")* (INDEX(Réponses!$B$2:$U$101,MATCH(G$1,Réponses!$A$2:$A$101,0),)<>"") ) /MAX(1,SUMPRODUCT( (INDEX(Réponses!$B$2:$U$101,MATCH($A8,Réponses!$A$2:$A$101,0),)<>"")* (INDEX(Réponses!$B$2:$U$101,MATCH(G$1,Réponses!$A$2:$A$101,0),)<>"") )),"")} -> 0 | H8: {=IFERROR( SUMPRODUCT( (INDEX(Réponses!$B$2:$U$101,MATCH($A8,Réponses!$A$2:$A$101,0),)=INDEX(Réponses!$B$2:$U$101,MATCH(H$1,Réponses!$A$2:$A$101,0),))* (INDEX(Réponses!$B$2:$U$101,MATCH($A8,Réponses!$A$2:$A$101,0),)<>"")* (INDEX(Réponses!$B$2:$U$101,MATCH(H$1,Réponses!$A$2:$A$101,0),)<>"") ) /MAX(1,SUMPRODUCT( (INDEX(Réponses!$B$2:$U$101,MATCH($A8,Réponses!$A$2:$A$101,0),)<>"")* (INDEX(Réponses!$B$2:$U$101,MATCH(H$1,Réponses!$A$2:$A$101,0),)<>"") )),"")} -> 1 | I8: {=IFERROR( SUMPRODUCT( (INDEX(Réponses!$B$2:$U$101,MATCH($A8,Réponses!$A$2:$A$101,0),)=INDEX(Réponses!$B$2:$U$101,MATCH(I$1,Réponses!$A$2:$A$101,0),))* (INDEX(Réponses!$B$2:$U$101,MATCH($A8,Réponses!$A$2:$A$101,0),)<>"")* (INDEX(Réponses!$B$2:$U$101,MATCH(I$1,Réponses!$A$2:$A$101,0),)<>"") ) /MAX(1,SUMPRODUCT( (INDEX(Réponses!$B$2:$U$101,MATCH($A8,Réponses!$A$2:$A$101,0),)<>"")* (INDEX(Réponses!$B$2:$U$101,MATCH(I$1,Réponses!$A$2:$A$101,0),)<>"") )),"")} -> 0 | ... CW8: {=IFERROR( SUMPRODUCT( (INDEX(Réponses!$B$2:$U$101,MATCH($A8,Réponses!$A$2:$A$101,0),)=INDEX(Réponses!$B$2:$U$101,MATCH(CW$1,Réponses!$A$2:$A$101,0),))* (INDEX(Réponses!$B$2:$U$101,MATCH($A8,Réponses!$A$2:$A$101,0),)<>"")* (INDEX(Réponses!$B$2:$U$101,MATCH(CW$1,Réponses!$A$2:$A$101,0),)<>"") ) /MAX(1,SUMPRODUCT( (INDEX(Réponses!$B$2:$U$101,MATCH($A8,Réponses!$A$2:$A$101,0),)<>"")* (INDEX(Réponses!$B$2:$U$101,MATCH(CW$1,Réponses!$A$2:$A$101,0),)<>"") )),"")} -> 0
A9: 8 | B9: {=IFERROR( SUMPRODUCT( (INDEX(Réponses!$B$2:$U$101,MATCH($A9,Réponses!$A$2:$A$101,0),)=INDEX(Réponses!$B$2:$U$101,MATCH(B$1,Réponses!$A$2:$A$101,0),))* (INDEX(Réponses!$B$2:$U$101,MATCH($A9,Réponses!$A$2:$A$101,0),)<>"")* (INDEX(Réponses!$B$2:$U$101,MATCH(B$1,Réponses!$A$2:$A$101,0),)<>"") ) /MAX(1,SUMPRODUCT( (INDEX(Réponses!$B$2:$U$101,MATCH($A9,Réponses!$A$2:$A$101,0),)<>"")* (INDEX(Réponses!$B$2:$U$101,MATCH(B$1,Réponses!$A$2:$A$101,0),)<>"") )),"")} -> 0.1 | C9: {=IFERROR( SUMPRODUCT( (INDEX(Réponses!$B$2:$U$101,MATCH($A9,Réponses!$A$2:$A$101,0),)=INDEX(Réponses!$B$2:$U$101,MATCH(C$1,Réponses!$A$2:$A$101,0),))* (INDEX(Réponses!$B$2:$U$101,MATCH($A9,Réponses!$A$2:$A$101,0),)<>"")* (INDEX(Réponses!$B$2:$U$101,MATCH(C$1,Réponses!$A$2:$A$101,0),)<>"") ) /MAX(1,SUMPRODUCT( (INDEX(Réponses!$B$2:$U$101,MATCH($A9,Réponses!$A$2:$A$101,0),)<>"")* (INDEX(Réponses!$B$2:$U$101,MATCH(C$1,Réponses!$A$2:$A$101,0),)<>"") )),"")} -> 0.05 | D9: {=IFERROR( SUMPRODUCT( (INDEX(Réponses!$B$2:$U$101,MATCH($A9,Réponses!$A$2:$A$101,0),)=INDEX(Réponses!$B$2:$U$101,MATCH(D$1,Réponses!$A$2:$A$101,0),))* (INDEX(Réponses!$B$2:$U$101,MATCH($A9,Réponses!$A$2:$A$101,0),)<>"")* (INDEX(Réponses!$B$2:$U$101,MATCH(D$1,Réponses!$A$2:$A$101,0),)<>"") ) /MAX(1,SUMPRODUCT( (INDEX(Réponses!$B$2:$U$101,MATCH($A9,Réponses!$A$2:$A$101,0),)<>"")* (INDEX(Réponses!$B$2:$U$101,MATCH(D$1,Réponses!$A$2:$A$101,0),)<>"") )),"")} -> 0 | E9: {=IFERROR( SUMPRODUCT( (INDEX(Réponses!$B$2:$U$101,MATCH($A9,Réponses!$A$2:$A$101,0),)=INDEX(Réponses!$B$2:$U$101,MATCH(E$1,Réponses!$A$2:$A$101,0),))* (INDEX(Réponses!$B$2:$U$101,MATCH($A9,Réponses!$A$2:$A$101,0),)<>"")* (INDEX(Réponses!$B$2:$U$101,MATCH(E$1,Réponses!$A$2:$A$101,0),)<>"") ) /MAX(1,SUMPRODUCT( (INDEX(Réponses!$B$2:$U$101,MATCH($A9,Réponses!$A$2:$A$101,0),)<>"")* (INDEX(Réponses!$B$2:$U$101,MATCH(E$1,Réponses!$A$2:$A$101,0),)<>"") )),"")} -> 0 | F9: {=IFERROR( SUMPRODUCT( (INDEX(Réponses!$B$2:$U$101,MATCH($A9,Réponses!$A$2:$A$101,0),)=INDEX(Réponses!$B$2:$U$101,MATCH(F$1,Réponses!$A$2:$A$101,0),))* (INDEX(Réponses!$B$2:$U$101,MATCH($A9,Réponses!$A$2:$A$101,0),)<>"")* (INDEX(Réponses!$B$2:$U$101,MATCH(F$1,Réponses!$A$2:$A$101,0),)<>"") ) /MAX(1,SUMPRODUCT( (INDEX(Réponses!$B$2:$U$101,MATCH($A9,Réponses!$A$2:$A$101,0),)<>"")* (INDEX(Réponses!$B$2:$U$101,MATCH(F$1,Réponses!$A$2:$A$101,0),)<>"") )),"")} -> 0 | G9: {=IFERROR( SUMPRODUCT( (INDEX(Réponses!$B$2:$U$101,MATCH($A9,Réponses!$A$2:$A$101,0),)=INDEX(Réponses!$B$2:$U$101,MATCH(G$1,Réponses!$A$2:$A$101,0),))* (INDEX(Réponses!$B$2:$U$101,MATCH($A9,Réponses!$A$2:$A$101,0),)<>"")* (INDEX(Réponses!$B$2:$U$101,MATCH(G$1,Réponses!$A$2:$A$101,0),)<>"") ) /MAX(1,SUMPRODUCT( (INDEX(Réponses!$B$2:$U$101,MATCH($A9,Réponses!$A$2:$A$101,0),)<>"")* (INDEX(Réponses!$B$2:$U$101,MATCH(G$1,Réponses!$A$2:$A$101,0),)<>"") )),"")} -> 0 | H9: {=IFERROR( SUMPRODUCT( (INDEX(Réponses!$B$2:$U$101,MATCH($A9,Réponses!$A$2:$A$101,0),)=INDEX(Réponses!$B$2:$U$101,MATCH(H$1,Réponses!$A$2:$A$101,0),))* (INDEX(Réponses!$B$2:$U$101,MATCH($A9,Réponses!$A$2:$A$101,0),)<>"")* (INDEX(Réponses!$B$2:$U$101,MATCH(H$1,Réponses!$A$2:$A$101,0),)<>"") ) /MAX(1,SUMPRODUCT( (INDEX(Réponses!$B$2:$U$101,MATCH($A9,Réponses!$A$2:$A$101,0),)<>"")* (INDEX(Réponses!$B$2:$U$101,MATCH(H$1,Réponses!$A$2:$A$101,0),)<>"") )),"")} -> 0 | I9: {=IFERROR( SUMPRODUCT( (INDEX(Réponses!$B$2:$U$101,MATCH($A9,Réponses!$A$2:$A$101,0),)=INDEX(Réponses!$B$2:$U$101,MATCH(I$1,Réponses!$A$2:$A$101,0),))* (INDEX(Réponses!$B$2:$U$101,MATCH($A9,Réponses!$A$2:$A$101,0),)<>"")* (INDEX(Réponses!$B$2:$U$101,MATCH(I$1,Réponses!$A$2:$A$101,0),)<>"") ) /MAX(1,SUMPRODUCT( (INDEX(Réponses!$B$2:$U$101,MATCH($A9,Réponses!$A$2:$A$101,0),)<>"")* (INDEX(Réponses!$B$2:$U$101,MATCH(I$1,Réponses!$A$2:$A$101,0),)<>"") )),"")} -> 1 | ... CW9: {=IFERROR( SUMPRODUCT( (INDEX(Réponses!$B$2:$U$101,MATCH($A9,Réponses!$A$2:$A$101,0),)=INDEX(Réponses!$B$2:$U$101,MATCH(CW$1,Réponses!$A$2:$A$101,0),))* (INDEX(Réponses!$B$2:$U$101,MATCH($A9,Réponses!$A$2:$A$101,0),)<>"")* (INDEX(Réponses!$B$2:$U$101,MATCH(CW$1,Réponses!$A$2:$A$101,0),)<>"") ) /MAX(1,SUMPRODUCT( (INDEX(Réponses!$B$2:$U$101,MATCH($A9,Réponses!$A$2:$A$101,0),)<>"")* (INDEX(Réponses!$B$2:$U$101,MATCH(CW$1,Réponses!$A$2:$A$101,0),)<>"") )),"")} -> 0
A10: 9 | B10: {=IFERROR( SUMPRODUCT( (INDEX(Réponses!$B$2:$U$101,MATCH($A10,Réponses!$A$2:$A$101,0),)=INDEX(Réponses!$B$2:$U$101,MATCH(B$1,Réponses!$A$2:$A$101,0),))* (INDEX(Réponses!$B$2:$U$101,MATCH($A10,Réponses!$A$2:$A$101,0),)<>"")* (INDEX(Réponses!$B$2:$U$101,MATCH(B$1,Réponses!$A$2:$A$101,0),)<>"") ) /MAX(1,SUMPRODUCT( (INDEX(Réponses!$B$2:$U$101,MATCH($A10,Réponses!$A$2:$A$101,0),)<>"")* (INDEX(Réponses!$B$2:$U$101,MATCH(B$1,Réponses!$A$2:$A$101,0),)<>"") )),"")} -> 0 | C10: {=IFERROR( SUMPRODUCT( (INDEX(Réponses!$B$2:$U$101,MATCH($A10,Réponses!$A$2:$A$101,0),)=INDEX(Réponses!$B$2:$U$101,MATCH(C$1,Réponses!$A$2:$A$101,0),))* (INDEX(Réponses!$B$2:$U$101,MATCH($A10,Réponses!$A$2:$A$101,0),)<>"")* (INDEX(Réponses!$B$2:$U$101,MATCH(C$1,Réponses!$A$2:$A$101,0),)<>"") ) /MAX(1,SUMPRODUCT( (INDEX(Réponses!$B$2:$U$101,MATCH($A10,Réponses!$A$2:$A$101,0),)<>"")* (INDEX(Réponses!$B$2:$U$101,MATCH(C$1,Réponses!$A$2:$A$101,0),)<>"") )),"")} -> 0 | D10: {=IFERROR( SUMPRODUCT( (INDEX(Réponses!$B$2:$U$101,MATCH($A10,Réponses!$A$2:$A$101,0),)=INDEX(Réponses!$B$2:$U$101,MATCH(D$1,Réponses!$A$2:$A$101,0),))* (INDEX(Réponses!$B$2:$U$101,MATCH($A10,Réponses!$A$2:$A$101,0),)<>"")* (INDEX(Réponses!$B$2:$U$101,MATCH(D$1,Réponses!$A$2:$A$101,0),)<>"") ) /MAX(1,SUMPRODUCT( (INDEX(Réponses!$B$2:$U$101,MATCH($A10,Réponses!$A$2:$A$101,0),)<>"")* (INDEX(Réponses!$B$2:$U$101,MATCH(D$1,Réponses!$A$2:$A$101,0),)<>"") )),"")} -> 0 | E10: {=IFERROR( SUMPRODUCT( (INDEX(Réponses!$B$2:$U$101,MATCH($A10,Réponses!$A$2:$A$101,0),)=INDEX(Réponses!$B$2:$U$101,MATCH(E$1,Réponses!$A$2:$A$101,0),))* (INDEX(Réponses!$B$2:$U$101,MATCH($A10,Réponses!$A$2:$A$101,0),)<>"")* (INDEX(Réponses!$B$2:$U$101,MATCH(E$1,Réponses!$A$2:$A$101,0),)<>"") ) /MAX(1,SUMPRODUCT( (INDEX(Réponses!$B$2:$U$101,MATCH($A10,Réponses!$A$2:$A$101,0),)<>"")* (INDEX(Réponses!$B$2:$U$101,MATCH(E$1,Réponses!$A$2:$A$101,0),)<>"") )),"")} -> 0 | F10: {=IFERROR( SUMPRODUCT( (INDEX(Réponses!$B$2:$U$101,MATCH($A10,Réponses!$A$2:$A$101,0),)=INDEX(Réponses!$B$2:$U$101,MATCH(F$1,Réponses!$A$2:$A$101,0),))* (INDEX(Réponses!$B$2:$U$101,MATCH($A10,Réponses!$A$2:$A$101,0),)<>"")* (INDEX(Réponses!$B$2:$U$101,MATCH(F$1,Réponses!$A$2:$A$101,0),)<>"") ) /MAX(1,SUMPRODUCT( (INDEX(Réponses!$B$2:$U$101,MATCH($A10,Réponses!$A$2:$A$101,0),)<>"")* (INDEX(Réponses!$B$2:$U$101,MATCH(F$1,Réponses!$A$2:$A$101,0),)<>"") )),"")} -> 0 | G10: {=IFERROR( SUMPRODUCT( (INDEX(Réponses!$B$2:$U$101,MATCH($A10,Réponses!$A$2:$A$101,0),)=INDEX(Réponses!$B$2:$U$101,MATCH(G$1,Réponses!$A$2:$A$101,0),))* (INDEX(Réponses!$B$2:$U$101,MATCH($A10,Réponses!$A$2:$A$101,0),)<>"")* (INDEX(Réponses!$B$2:$U$101,MATCH(G$1,Réponses!$A$2:$A$101,0),)<>"") ) /MAX(1,SUMPRODUCT( (INDEX(Réponses!$B$2:$U$101,MATCH($A10,Réponses!$A$2:$A$101,0),)<>"")* (INDEX(Réponses!$B$2:$U$101,MATCH(G$1,Réponses!$A$2:$A$101,0),)<>"") )),"")} -> 0 | H10: {=IFERROR( SUMPRODUCT( (INDEX(Réponses!$B$2:$U$101,MATCH($A10,Réponses!$A$2:$A$101,0),)=INDEX(Réponses!$B$2:$U$101,MATCH(H$1,Réponses!$A$2:$A$101,0),))* (INDEX(Réponses!$B$2:$U$101,MATCH($A10,Réponses!$A$2:$A$101,0),)<>"")* (INDEX(Réponses!$B$2:$U$101,MATCH(H$1,Réponses!$A$2:$A$101,0),)<>"") ) /MAX(1,SUMPRODUCT( (INDEX(Réponses!$B$2:$U$101,MATCH($A10,Réponses!$A$2:$A$101,0),)<>"")* (INDEX(Réponses!$B$2:$U$101,MATCH(H$1,Réponses!$A$2:$A$101,0),)<>"") )),"")} -> 0 | I10: {=IFERROR( SUMPRODUCT( (INDEX(Réponses!$B$2:$U$101,MATCH($A10,Réponses!$A$2:$A$101,0),)=INDEX(Réponses!$B$2:$U$101,MATCH(I$1,Réponses!$A$2:$A$101,0),))* (INDEX(Réponses!$B$2:$U$101,MATCH($A10,Réponses!$A$2:$A$101,0),)<>"")* (INDEX(Réponses!$B$2:$U$101,MATCH(I$1,Réponses!$A$2:$A$101,0),)<>"") ) /MAX(1,SUMPRODUCT( (INDEX(Réponses!$B$2:$U$101,MATCH($A10,Réponses!$A$2:$A$101,0),)<>"")* (INDEX(Réponses!$B$2:$U$101,MATCH(I$1,Réponses!$A$2:$A$101,0),)<>"") )),"")} -> 0 | ... CW10: {=IFERROR( SUMPRODUCT( (INDEX(Réponses!$B$2:$U$101,MATCH($A10,Réponses!$A$2:$A$101,0),)=INDEX(Réponses!$B$2:$U$101,MATCH(CW$1,Réponses!$A$2:$A$101,0),))* (INDEX(Réponses!$B$2:$U$101,MATCH($A10,Réponses!$A$2:$A$101,0),)<>"")* (INDEX(Réponses!$B$2:$U$101,MATCH(CW$1,Réponses!$A$2:$A$101,0),)<>"") ) /MAX(1,SUMPRODUCT( (INDEX(Réponses!$B$2:$U$101,MATCH($A10,Réponses!$A$2:$A$101,0),)<>"")* (INDEX(Réponses!$B$2:$U$101,MATCH(CW$1,Réponses!$A$2:$A$101,0),)<>"") )),"")} -> 0
A11: 10 | B11: {=IFERROR( SUMPRODUCT( (INDEX(Réponses!$B$2:$U$101,MATCH($A11,Réponses!$A$2:$A$101,0),)=INDEX(Réponses!$B$2:$U$101,MATCH(B$1,Réponses!$A$2:$A$101,0),))* (INDEX(Réponses!$B$2:$U$101,MATCH($A11,Réponses!$A$2:$A$101,0),)<>"")* (INDEX(Réponses!$B$2:$U$101,MATCH(B$1,Réponses!$A$2:$A$101,0),)<>"") ) /MAX(1,SUMPRODUCT( (INDEX(Réponses!$B$2:$U$101,MATCH($A11,Réponses!$A$2:$A$101,0),)<>"")* (INDEX(Réponses!$B$2:$U$101,MATCH(B$1,Réponses!$A$2:$A$101,0),)<>"") )),"")} -> 0 | C11: {=IFERROR( SUMPRODUCT( (INDEX(Réponses!$B$2:$U$101,MATCH($A11,Réponses!$A$2:$A$101,0),)=INDEX(Réponses!$B$2:$U$101,MATCH(C$1,Réponses!$A$2:$A$101,0),))* (INDEX(Réponses!$B$2:$U$101,MATCH($A11,Réponses!$A$2:$A$101,0),)<>"")* (INDEX(Réponses!$B$2:$U$101,MATCH(C$1,Réponses!$A$2:$A$101,0),)<>"") ) /MAX(1,SUMPRODUCT( (INDEX(Réponses!$B$2:$U$101,MATCH($A11,Réponses!$A$2:$A$101,0),)<>"")* (INDEX(Réponses!$B$2:$U$101,MATCH(C$1,Réponses!$A$2:$A$101,0),)<>"") )),"")} -> 0 | D11: {=IFERROR( SUMPRODUCT( (INDEX(Réponses!$B$2:$U$101,MATCH($A11,Réponses!$A$2:$A$101,0),)=INDEX(Réponses!$B$2:$U$101,MATCH(D$1,Réponses!$A$2:$A$101,0),))* (INDEX(Réponses!$B$2:$U$101,MATCH($A11,Réponses!$A$2:$A$101,0),)<>"")* (INDEX(Réponses!$B$2:$U$101,MATCH(D$1,Réponses!$A$2:$A$101,0),)<>"") ) /MAX(1,SUMPRODUCT( (INDEX(Réponses!$B$2:$U$101,MATCH($A11,Réponses!$A$2:$A$101,0),)<>"")* (INDEX(Réponses!$B$2:$U$101,MATCH(D$1,Réponses!$A$2:$A$101,0),)<>"") )),"")} -> 0 | E11: {=IFERROR( SUMPRODUCT( (INDEX(Réponses!$B$2:$U$101,MATCH($A11,Réponses!$A$2:$A$101,0),)=INDEX(Réponses!$B$2:$U$101,MATCH(E$1,Réponses!$A$2:$A$101,0),))* (INDEX(Réponses!$B$2:$U$101,MATCH($A11,Réponses!$A$2:$A$101,0),)<>"")* (INDEX(Réponses!$B$2:$U$101,MATCH(E$1,Réponses!$A$2:$A$101,0),)<>"") ) /MAX(1,SUMPRODUCT( (INDEX(Réponses!$B$2:$U$101,MATCH($A11,Réponses!$A$2:$A$101,0),)<>"")* (INDEX(Réponses!$B$2:$U$101,MATCH(E$1,Réponses!$A$2:$A$101,0),)<>"") )),"")} -> 1 | F11: {=IFERROR( SUMPRODUCT( (INDEX(Réponses!$B$2:$U$101,MATCH($A11,Réponses!$A$2:$A$101,0),)=INDEX(Réponses!$B$2:$U$101,MATCH(F$1,Réponses!$A$2:$A$101,0),))* (INDEX(Réponses!$B$2:$U$101,MATCH($A11,Réponses!$A$2:$A$101,0),)<>"")* (INDEX(Réponses!$B$2:$U$101,MATCH(F$1,Réponses!$A$2:$A$101,0),)<>"") ) /MAX(1,SUMPRODUCT( (INDEX(Réponses!$B$2:$U$101,MATCH($A11,Réponses!$A$2:$A$101,0),)<>"")* (INDEX(Réponses!$B$2:$U$101,MATCH(F$1,Réponses!$A$2:$A$101,0),)<>"") )),"")} -> 0 | G11: {=IFERROR( SUMPRODUCT( (INDEX(Réponses!$B$2:$U$101,MATCH($A11,Réponses!$A$2:$A$101,0),)=INDEX(Réponses!$B$2:$U$101,MATCH(G$1,Réponses!$A$2:$A$101,0),))* (INDEX(Réponses!$B$2:$U$101,MATCH($A11,Réponses!$A$2:$A$101,0),)<>"")* (INDEX(Réponses!$B$2:$U$101,MATCH(G$1,Réponses!$A$2:$A$101,0),)<>"") ) /MAX(1,SUMPRODUCT( (INDEX(Réponses!$B$2:$U$101,MATCH($A11,Réponses!$A$2:$A$101,0),)<>"")* (INDEX(Réponses!$B$2:$U$101,MATCH(G$1,Réponses!$A$2:$A$101,0),)<>"") )),"")} -> 0 | H11: {=IFERROR( SUMPRODUCT( (INDEX(Réponses!$B$2:$U$101,MATCH($A11,Réponses!$A$2:$A$101,0),)=INDEX(Réponses!$B$2:$U$101,MATCH(H$1,Réponses!$A$2:$A$101,0),))* (INDEX(Réponses!$B$2:$U$101,MATCH($A11,Réponses!$A$2:$A$101,0),)<>"")* (INDEX(Réponses!$B$2:$U$101,MATCH(H$1,Réponses!$A$2:$A$101,0),)<>"") ) /MAX(1,SUMPRODUCT( (INDEX(Réponses!$B$2:$U$101,MATCH($A11,Réponses!$A$2:$A$101,0),)<>"")* (INDEX(Réponses!$B$2:$U$101,MATCH(H$1,Réponses!$A$2:$A$101,0),)<>"") )),"")} -> 0 | I11: {=IFERROR( SUMPRODUCT( (INDEX(Réponses!$B$2:$U$101,MATCH($A11,Réponses!$A$2:$A$101,0),)=INDEX(Réponses!$B$2:$U$101,MATCH(I$1,Réponses!$A$2:$A$101,0),))* (INDEX(Réponses!$B$2:$U$101,MATCH($A11,Réponses!$A$2:$A$101,0),)<>"")* (INDEX(Réponses!$B$2:$U$101,MATCH(I$1,Réponses!$A$2:$A$101,0),)<>"") ) /MAX(1,SUMPRODUCT( (INDEX(Réponses!$B$2:$U$101,MATCH($A11,Réponses!$A$2:$A$101,0),)<>"")* (INDEX(Réponses!$B$2:$U$101,MATCH(I$1,Réponses!$A$2:$A$101,0),)<>"") )),"")} -> 0 | ... CW11: {=IFERROR( SUMPRODUCT( (INDEX(Réponses!$B$2:$U$101,MATCH($A11,Réponses!$A$2:$A$101,0),)=INDEX(Réponses!$B$2:$U$101,MATCH(CW$1,Réponses!$A$2:$A$101,0),))* (INDEX(Réponses!$B$2:$U$101,MATCH($A11,Réponses!$A$2:$A$101,0),)<>"")* (INDEX(Réponses!$B$2:$U$101,MATCH(CW$1,Réponses!$A$2:$A$101,0),)<>"") ) /MAX(1,SUMPRODUCT( (INDEX(Réponses!$B$2:$U$101,MATCH($A11,Réponses!$A$2:$A$101,0),)<>"")* (INDEX(Réponses!$B$2:$U$101,MATCH(CW$1,Réponses!$A$2:$A$101,0),)<>"") )),"")} -> 0
A12: 11 | B12: {=IFERROR( SUMPRODUCT( (INDEX(Réponses!$B$2:$U$101,MATCH($A12,Réponses!$A$2:$A$101,0),)=INDEX(Réponses!$B$2:$U$101,MATCH(B$1,Réponses!$A$2:$A$101,0),))* (INDEX(Réponses!$B$2:$U$101,MATCH($A12,Réponses!$A$2:$A$101,0),)<>"")* (INDEX(Réponses!$B$2:$U$101,MATCH(B$1,Réponses!$A$2:$A$101,0),)<>"") ) /MAX(1,SUMPRODUCT( (INDEX(Réponses!$B$2:$U$101,MATCH($A12,Réponses!$A$2:$A$101,0),)<>"")* (INDEX(Réponses!$B$2:$U$101,MATCH(B$1,Réponses!$A$2:$A$101,0),)<>"") )),"")} -> 0.1 | C12: {=IFERROR( SUMPRODUCT( (INDEX(Réponses!$B$2:$U$101,MATCH($A12,Réponses!$A$2:$A$101,0),)=INDEX(Réponses!$B$2:$U$101,MATCH(C$1,Réponses!$A$2:$A$101,0),))* (INDEX(Réponses!$B$2:$U$101,MATCH($A12,Réponses!$A$2:$A$101,0),)<>"")* (INDEX(Réponses!$B$2:$U$101,MATCH(C$1,Réponses!$A$2:$A$101,0),)<>"") ) /MAX(1,SUMPRODUCT( (INDEX(Réponses!$B$2:$U$101,MATCH($A12,Réponses!$A$2:$A$101,0),)<>"")* (INDEX(Réponses!$B$2:$U$101,MATCH(C$1,Réponses!$A$2:$A$101,0),)<>"") )),"")} -> 0.05 | D12: {=IFERROR( SUMPRODUCT( (INDEX(Réponses!$B$2:$U$101,MATCH($A12,Réponses!$A$2:$A$101,0),)=INDEX(Réponses!$B$2:$U$101,MATCH(D$1,Réponses!$A$2:$A$101,0),))* (INDEX(Réponses!$B$2:$U$101,MATCH($A12,Réponses!$A$2:$A$101,0),)<>"")* (INDEX(Réponses!$B$2:$U$101,MATCH(D$1,Réponses!$A$2:$A$101,0),)<>"") ) /MAX(1,SUMPRODUCT( (INDEX(Réponses!$B$2:$U$101,MATCH($A12,Réponses!$A$2:$A$101,0),)<>"")* (INDEX(Réponses!$B$2:$U$101,MATCH(D$1,Réponses!$A$2:$A$101,0),)<>"") )),"")} -> 0 | E12: {=IFERROR( SUMPRODUCT( (INDEX(Réponses!$B$2:$U$101,MATCH($A12,Réponses!$A$2:$A$101,0),)=INDEX(Réponses!$B$2:$U$101,MATCH(E$1,Réponses!$A$2:$A$101,0),))* (INDEX(Réponses!$B$2:$U$101,MATCH($A12,Réponses!$A$2:$A$101,0),)<>"")* (INDEX(Réponses!$B$2:$U$101,MATCH(E$1,Réponses!$A$2:$A$101,0),)<>"") ) /MAX(1,SUMPRODUCT( (INDEX(Réponses!$B$2:$U$101,MATCH($A12,Réponses!$A$2:$A$101,0),)<>"")* (INDEX(Réponses!$B$2:$U$101,MATCH(E$1,Réponses!$A$2:$A$101,0),)<>"") )),"")} -> 0 | F12: {=IFERROR( SUMPRODUCT( (INDEX(Réponses!$B$2:$U$101,MATCH($A12,Réponses!$A$2:$A$101,0),)=INDEX(Réponses!$B$2:$U$101,MATCH(F$1,Réponses!$A$2:$A$101,0),))* (INDEX(Réponses!$B$2:$U$101,MATCH($A12,Réponses!$A$2:$A$101,0),)<>"")* (INDEX(Réponses!$B$2:$U$101,MATCH(F$1,Réponses!$A$2:$A$101,0),)<>"") ) /MAX(1,SUMPRODUCT( (INDEX(Réponses!$B$2:$U$101,MATCH($A12,Réponses!$A$2:$A$101,0),)<>"")* (INDEX(Réponses!$B$2:$U$101,MATCH(F$1,Réponses!$A$2:$A$101,0),)<>"") )),"")} -> 0 | G12: {=IFERROR( SUMPRODUCT( (INDEX(Réponses!$B$2:$U$101,MATCH($A12,Réponses!$A$2:$A$101,0),)=INDEX(Réponses!$B$2:$U$101,MATCH(G$1,Réponses!$A$2:$A$101,0),))* (INDEX(Réponses!$B$2:$U$101,MATCH($A12,Réponses!$A$2:$A$101,0),)<>"")* (INDEX(Réponses!$B$2:$U$101,MATCH(G$1,Réponses!$A$2:$A$101,0),)<>"") ) /MAX(1,SUMPRODUCT( (INDEX(Réponses!$B$2:$U$101,MATCH($A12,Réponses!$A$2:$A$101,0),)<>"")* (INDEX(Réponses!$B$2:$U$101,MATCH(G$1,Réponses!$A$2:$A$101,0),)<>"") )),"")} -> 0 | H12: {=IFERROR( SUMPRODUCT( (INDEX(Réponses!$B$2:$U$101,MATCH($A12,Réponses!$A$2:$A$101,0),)=INDEX(Réponses!$B$2:$U$101,MATCH(H$1,Réponses!$A$2:$A$101,0),))* (INDEX(Réponses!$B$2:$U$101,MATCH($A12,Réponses!$A$2:$A$101,0),)<>"")* (INDEX(Réponses!$B$2:$U$101,MATCH(H$1,Réponses!$A$2:$A$101,0),)<>"") ) /MAX(1,SUMPRODUCT( (INDEX(Réponses!$B$2:$U$101,MATCH($A12,Réponses!$A$2:$A$101,0),)<>"")* (INDEX(Réponses!$B$2:$U$101,MATCH(H$1,Réponses!$A$2:$A$101,0),)<>"") )),"")} -> 0 | I12: {=IFERROR( SUMPRODUCT( (INDEX(Réponses!$B$2:$U$101,MATCH($A12,Réponses!$A$2:$A$101,0),)=INDEX(Réponses!$B$2:$U$101,MATCH(I$1,Réponses!$A$2:$A$101,0),))* (INDEX(Réponses!$B$2:$U$101,MATCH($A12,Réponses!$A$2:$A$101,0),)<>"")* (INDEX(Réponses!$B$2:$U$101,MATCH(I$1,Réponses!$A$2:$A$101,0),)<>"") ) /MAX(1,SUMPRODUCT( (INDEX(Réponses!$B$2:$U$101,MATCH($A12,Réponses!$A$2:$A$101,0),)<>"")* (INDEX(Réponses!$B$2:$U$101,MATCH(I$1,Réponses!$A$2:$A$101,0),)<>"") )),"")} -> 1 | ... CW12: {=IFERROR( SUMPRODUCT( (INDEX(Réponses!$B$2:$U$101,MATCH($A12,Réponses!$A$2:$A$101,0),)=INDEX(Réponses!$B$2:$U$101,MATCH(CW$1,Réponses!$A$2:$A$101,0),))* (INDEX(Réponses!$B$2:$U$101,MATCH($A12,Réponses!$A$2:$A$101,0),)<>"")* (INDEX(Réponses!$B$2:$U$101,MATCH(CW$1,Réponses!$A$2:$A$101,0),)<>"") ) /MAX(1,SUMPRODUCT( (INDEX(Réponses!$B$2:$U$101,MATCH($A12,Réponses!$A$2:$A$101,0),)<>"")* (INDEX(Réponses!$B$2:$U$101,MATCH(CW$1,Réponses!$A$2:$A$101,0),)<>"") )),"")} -> 0
A13: 12 | B13: {=IFERROR( SUMPRODUCT( (INDEX(Réponses!$B$2:$U$101,MATCH($A13,Réponses!$A$2:$A$101,0),)=INDEX(Réponses!$B$2:$U$101,MATCH(B$1,Réponses!$A$2:$A$101,0),))* (INDEX(Réponses!$B$2:$U$101,MATCH($A13,Réponses!$A$2:$A$101,0),)<>"")* (INDEX(Réponses!$B$2:$U$101,MATCH(B$1,Réponses!$A$2:$A$101,0),)<>"") ) /MAX(1,SUMPRODUCT( (INDEX(Réponses!$B$2:$U$101,MATCH($A13,Réponses!$A$2:$A$101,0),)<>"")* (INDEX(Réponses!$B$2:$U$101,MATCH(B$1,Réponses!$A$2:$A$101,0),)<>"") )),"")} -> 0 | C13: {=IFERROR( SUMPRODUCT( (INDEX(Réponses!$B$2:$U$101,MATCH($A13,Réponses!$A$2:$A$101,0),)=INDEX(Réponses!$B$2:$U$101,MATCH(C$1,Réponses!$A$2:$A$101,0),))* (INDEX(Réponses!$B$2:$U$101,MATCH($A13,Réponses!$A$2:$A$101,0),)<>"")* (INDEX(Réponses!$B$2:$U$101,MATCH(C$1,Réponses!$A$2:$A$101,0),)<>"") ) /MAX(1,SUMPRODUCT( (INDEX(Réponses!$B$2:$U$101,MATCH($A13,Réponses!$A$2:$A$101,0),)<>"")* (INDEX(Réponses!$B$2:$U$101,MATCH(C$1,Réponses!$A$2:$A$101,0),)<>"") )),"")} -> 0 | D13: {=IFERROR( SUMPRODUCT( (INDEX(Réponses!$B$2:$U$101,MATCH($A13,Réponses!$A$2:$A$101,0),)=INDEX(Réponses!$B$2:$U$101,MATCH(D$1,Réponses!$A$2:$A$101,0),))* (INDEX(Réponses!$B$2:$U$101,MATCH($A13,Réponses!$A$2:$A$101,0),)<>"")* (INDEX(Réponses!$B$2:$U$101,MATCH(D$1,Réponses!$A$2:$A$101,0),)<>"") ) /MAX(1,SUMPRODUCT( (INDEX(Réponses!$B$2:$U$101,MATCH($A13,Réponses!$A$2:$A$101,0),)<>"")* (INDEX(Réponses!$B$2:$U$101,MATCH(D$1,Réponses!$A$2:$A$101,0),)<>"") )),"")} -> 0 | E13: {=IFERROR( SUMPRODUCT( (INDEX(Réponses!$B$2:$U$101,MATCH($A13,Réponses!$A$2:$A$101,0),)=INDEX(Réponses!$B$2:$U$101,MATCH(E$1,Réponses!$A$2:$A$101,0),))* (INDEX(Réponses!$B$2:$U$101,MATCH($A13,Réponses!$A$2:$A$101,0),)<>"")* (INDEX(Réponses!$B$2:$U$101,MATCH(E$1,Réponses!$A$2:$A$101,0),)<>"") ) /MAX(1,SUMPRODUCT( (INDEX(Réponses!$B$2:$U$101,MATCH($A13,Réponses!$A$2:$A$101,0),)<>"")* (INDEX(Réponses!$B$2:$U$101,MATCH(E$1,Réponses!$A$2:$A$101,0),)<>"") )),"")} -> 0 | F13: {=IFERROR( SUMPRODUCT( (INDEX(Réponses!$B$2:$U$101,MATCH($A13,Réponses!$A$2:$A$101,0),)=INDEX(Réponses!$B$2:$U$101,MATCH(F$1,Réponses!$A$2:$A$101,0),))* (INDEX(Réponses!$B$2:$U$101,MATCH($A13,Réponses!$A$2:$A$101,0),)<>"")* (INDEX(Réponses!$B$2:$U$101,MATCH(F$1,Réponses!$A$2:$A$101,0),)<>"") ) /MAX(1,SUMPRODUCT( (INDEX(Réponses!$B$2:$U$101,MATCH($A13,Réponses!$A$2:$A$101,0),)<>"")* (INDEX(Réponses!$B$2:$U$101,MATCH(F$1,Réponses!$A$2:$A$101,0),)<>"") )),"")} -> 0 | G13: {=IFERROR( SUMPRODUCT( (INDEX(Réponses!$B$2:$U$101,MATCH($A13,Réponses!$A$2:$A$101,0),)=INDEX(Réponses!$B$2:$U$101,MATCH(G$1,Réponses!$A$2:$A$101,0),))* (INDEX(Réponses!$B$2:$U$101,MATCH($A13,Réponses!$A$2:$A$101,0),)<>"")* (INDEX(Réponses!$B$2:$U$101,MATCH(G$1,Réponses!$A$2:$A$101,0),)<>"") ) /MAX(1,SUMPRODUCT( (INDEX(Réponses!$B$2:$U$101,MATCH($A13,Réponses!$A$2:$A$101,0),)<>"")* (INDEX(Réponses!$B$2:$U$101,MATCH(G$1,Réponses!$A$2:$A$101,0),)<>"") )),"")} -> 1 | H13: {=IFERROR( SUMPRODUCT( (INDEX(Réponses!$B$2:$U$101,MATCH($A13,Réponses!$A$2:$A$101,0),)=INDEX(Réponses!$B$2:$U$101,MATCH(H$1,Réponses!$A$2:$A$101,0),))* (INDEX(Réponses!$B$2:$U$101,MATCH($A13,Réponses!$A$2:$A$101,0),)<>"")* (INDEX(Réponses!$B$2:$U$101,MATCH(H$1,Réponses!$A$2:$A$101,0),)<>"") ) /MAX(1,SUMPRODUCT( (INDEX(Réponses!$B$2:$U$101,MATCH($A13,Réponses!$A$2:$A$101,0),)<>"")* (INDEX(Réponses!$B$2:$U$101,MATCH(H$1,Réponses!$A$2:$A$101,0),)<>"") )),"")} -> 0 | I13: {=IFERROR( SUMPRODUCT( (INDEX(Réponses!$B$2:$U$101,MATCH($A13,Réponses!$A$2:$A$101,0),)=INDEX(Réponses!$B$2:$U$101,MATCH(I$1,Réponses!$A$2:$A$101,0),))* (INDEX(Réponses!$B$2:$U$101,MATCH($A13,Réponses!$A$2:$A$101,0),)<>"")* (INDEX(Réponses!$B$2:$U$101,MATCH(I$1,Réponses!$A$2:$A$101,0),)<>"") ) /MAX(1,SUMPRODUCT( (INDEX(Réponses!$B$2:$U$101,MATCH($A13,Réponses!$A$2:$A$101,0),)<>"")* (INDEX(Réponses!$B$2:$U$101,MATCH(I$1,Réponses!$A$2:$A$101,0),)<>"") )),"")} -> 0 | ... CW13: {=IFERROR( SUMPRODUCT( (INDEX(Réponses!$B$2:$U$101,MATCH($A13,Réponses!$A$2:$A$101,0),)=INDEX(Réponses!$B$2:$U$101,MATCH(CW$1,Réponses!$A$2:$A$101,0),))* (INDEX(Réponses!$B$2:$U$101,MATCH($A13,Réponses!$A$2:$A$101,0),)<>"")* (INDEX(Réponses!$B$2:$U$101,MATCH(CW$1,Réponses!$A$2:$A$101,0),)<>"") ) /MAX(1,SUMPRODUCT( (INDEX(Réponses!$B$2:$U$101,MATCH($A13,Réponses!$A$2:$A$101,0),)<>"")* (INDEX(Réponses!$B$2:$U$101,MATCH(CW$1,Réponses!$A$2:$A$101,0),)<>"") )),"")} -> 0
